Workbook
Name _ftn1: 'Pathways emissions'!$B$14
Name _ftn2: 'Pathways emissions'!$B$15
Name _ftn3: 'Pathways emissions'!$B$16
Name _ftn4: 'Pathways emissions'!$B$17
Name _ftnref1: 'Pathways emissions'!$B$2
Name _ftnref2: 'Pathways emissions'!$D$2
Name _ftnref3: 'Pathways emissions'!$E$2
Name _ftnref4: 'Pathways emissions'!$F$2

Sheet WFH Recoverable LACW DATA 2022
A1: Council Name | B1: TotalCollected2022 | C1: total recycled collected | D1: Residual_2022 | E1: Foodwaste total | F1: Garden&OrganicWaste total | G1: PaperampCard total | H1: Plastics total | I1: Glass total | J1: Metals total | K1: Textile total | L1: WEEE total | M1: Wood Total | N1: Other Total | O1: FoodCompostedIV_2022 | P1: FoodCompostedW_2022 | Q1: FoodAD_2022 | R1: FoodEfW_2022 | S1: FoodLandfill_2022 | T1: GardenCompostedIV_2022 | U1: GardenCompostedW_2022 | V1: GardenAD_2022 | W1: GardenEfW_2022 | X1: GardenIncNoEnergy_2022 | Y1: GardenLandfill_2022 | Z1: PaperCardRecycled_2022 | AA1: PaperCardReuse_2022 | AB1: PaperCardRDF_MHT_2022 | AC1: PaperCardEfW_2022 | AD1: PaperCardLandfill_2022 | AE1: PlasticsRecycled_2022 | AF1: PlasticsReuse_2022 | AG1: PlasticsEfW_2022 | AH1: PlasticsLandfill_2022 | AI1: GlassRecycled_2022 | AJ1: GlassReuse_2022 | AK1: GlassRDF_MHT_2022 | AL1: GlassEfW_2022 | AM1: GlassLandfill_2022 | AN1: MetalsRecycled_2022 | AO1: MetalsReuse_2022 | AP1: MetalsEfW_2022 | AQ1: MetalsLandfill_2022 | AR1: TextilesRecycled_2022 | AS1: TextilesReuse_2022 | AT1: TextilesRDF_MHT_2022 | AU1: TextilesEfW_2022 | AV1: TextilesLandfill_2022 | AW1: WEEERecycled_2022 | AX1: WEEEReuse_2022 | AY1: WEEERDF_MHT_2022 | AZ1: WEEEEfW_2022 | BA1: WEEEIncNoEnergy_2022 | BB1: WEEELandfill_2022 | BC1: WoodRecycled_2022 | BD1: WoodReuse_2022 | BE1: WoodCompostedIV_2022 | BF1: WoodCompostedW_2022 | BG1: WoodRDF_MHT_2022 | BH1: WoodEfW_2022 | BI1: WoodIncNoEnergy_2022 | BJ1: WoodLandfill_2022 | BK1: OtherRecyclablesRecycled_2022 | BL1: OtherRecyclablesReuse_2022 | BM1: OtherRecyclablesRDF_MHT_2022 | BN1: OtherRecyclablesEfW_2022 | BO1: OtherRecyclablesLandfill_2022 | BP1: Council Name | BQ1: TotalCollected2022 | BR1: TotalRecCollec2022 | BS1: Residual_2022 | BT1: FoodCollected_2022 | BU1: GardenCollected_2022 | BV1: PaperCardCollected_2022 | BW1: PlasticsCollected_2022 | BX1: GlassCollected_2022 | BY1: MetalsCollected_2022 | BZ1: TextilesCollected_2022 | CA1: WEEECollected_2022 | CB1: WoodCollected_2022 | CC1: OtherRecyclablesCollected_2022 | CD1: FoodCompostedIV_2022 | CE1: FoodCompostedW_2022 | CF1: FoodAD_2022 | CG1: FoodEfW_2022 | CH1: FoodLandfill_2022 | CI1: GardenCompostedIV_2022 | CJ1: GardenCompostedW_2022 | CK1: GardenAD_2022 | CL1: GardenEfW_2022 | CM1: GardenIncNoEnergy_2022 | CN1: GardenLandfill_2022 | CO1: PaperCardRecycled_2022 | CP1: PaperCardReuse_2022 | CQ1: PaperCardRDF_MHT_2022 | CR1: PaperCardEfW_2022 | CS1: PaperCardLandfill_2022 | CT1: PlasticsRecycled_2022 | CU1: PlasticsReuse_2022 | CV1: PlasticsEfW_2022 | CW1: PlasticsLandfill_2022 | CX1: GlassRecycled_2022 | CY1: GlassReuse_2022 | CZ1: GlassRDF_MHT_2022 | DA1: GlassEfW_2022 | DB1: GlassLandfill_2022 | DC1: MetalsRecycled_2022 | DD1: MetalsReuse_2022 | DE1: MetalsEfW_2022 | DF1: MetalsLandfill_2022 | DG1: TextilesRecycled_2022 | DH1: TextilesReuse_2022 | DI1: TextilesRDF_MHT_2022 | DJ1: TextilesEfW_2022 | DK1: TextilesLandfill_2022 | DL1: WEEERecycled_2022 | DM1: WEEEReuse_2022 | DN1: WEEERDF_MHT_2022 | DO1: WEEEEfW_2022 | DP1: WEEEIncNoEnergy_2022 | DQ1: WEEELandfill_2022 | DR1: WoodRecycled_2022 | DS1: WoodReuse_2022 | DT1: WoodCompostedIV_2022 | DU1: WoodCompostedW_2022 | DV1: WoodRDF_MHT_2022 | DW1: WoodEfW_2022 | DX1: WoodIncNoEnergy_2022 | DY1: WoodLandfill_2022 | DZ1: OtherRecyclablesRecycled_2022 | EA1: OtherRecyclablesReuse_2022 | EB1: OtherRecyclablesRDF_MHT_2022 | EC1: OtherRecyclablesEfW_2022 | ED1: OtherRecyclablesLandfill_2022 | EE1: Share FoodCompostedIV_2022 | EF1: Share FoodCompostedW_2022 | EG1: Share FoodAD_2022 | EH1: Share FoodEfW_2022 | EI1: Share FoodLandfill_2022 | EJ1: Share GardenCompostedIV_2022 | EK1: Share GardenCompostedW_2022 | EL1: Share GardenAD_2022 | EM1: Share GardenEfW_2022 | EN1: Share GardenIncNoEnergy_2022 | EO1: Share GardenLandfill_2022 | EP1: Share PaperCardRecycled_2022 | EQ1: PaperCardReuse_2022 | ER1: PaperCardRDF_MHT_2022 | ES1: PaperCardEfW_2022 | ET1: PaperCardLandfill_2022 | EU1: PlasticsRecycled_2022 | EV1: PlasticsReuse_2022 | EW1: PlasticsEfW_2022 | EX1: PlasticsLandfill_2022 | EY1: GlassRecycled_2022 | EZ1: GlassReuse_2022 | FA1: GlassRDF_MHT_2022 | FB1: GlassEfW_2022 | FC1: GlassLandfill_2022 | FD1: MetalsRecycled_2022 | FE1: MetalsReuse_2022 | FF1: MetalsEfW_2022 | FG1: MetalsLandfill_2022 | FH1: TextilesRecycled_2022 | FI1: TextilesReuse_2022 | FJ1: TextilesRDF_MHT_2022 | FK1: TextilesEfW_2022 | FL1: TextilesLandfill_2022 | FM1: WEEERecycled_2022 | FN1: WEEEReuse_2022 | FO1: WEEERDF_MHT_2022 | FP1: WEEEEfW_2022 | FQ1: WEEEIncNoEnergy_2022 | FR1: WEEELandfill_2022 | FS1: WoodRecycled_2022 | FT1: WoodReuse_2022 | FU1: WoodCompostedIV_2022 | FV1: WoodCompostedW_2022 | FW1: WoodRDF_MHT_2022 | FX1: WoodEfW_2022 | FY1: WoodIncNoEnergy_2022 | FZ1: WoodLandfill_2022 | GA1: OtherRecyclablesRecycled_2022 | GB1: OtherRecyclablesReuse_2022 | GC1: OtherRecyclablesRDF_MHT_2022 | GD1: OtherRecyclablesEfW_2022 | GE1: OtherRecyclablesLandfill_2022
A2: Adur | B2: 12925.573 | C2: =B2-D2 -> 9816.7109 | D2: 3108.8621 | E2: 11.4 | F2: 2200.2 | G2: 2937.2981 | H2: 465.73312 | I2: 2014.3283 | J2: 408.93985 | K2: 29.183 | L2: 26.676337 | M2: 0 | N2: 1722.9522 | O2: =EE2*E2 -> 0 | P2: =EF2*E2 -> 0 | Q2: =EG2*E2 -> 2.1037406 | R2: =EH2*E2 -> 0 | S2: =EI2*E2 -> 0 | T2: =EJ2*F2 -> 0 | U2: =EK2*F2 -> 2200.2 | V2: =EL2*F2 -> 0 | W2: =EM2*F2 -> 0 | X2: =EN2*F2 -> 0 | Y2: =EO2*F2 -> 0 | Z2: =EP2*G2 -> 2937.2981 | AA2: =EQ2*G2 -> 0 | AB2: =ER2*G2 -> 0 | AC2: =ES2*G2 -> 0 | AD2: =ET2*G2 -> 0 | AE2: =EU2*H2 -> 464.83542 | AF2: =EV2*H2 -> 0 | AG2: =EW2*H2 -> 0 | AH2: =EX2*H2 -> 0.89769894 | AI2: =EY2*I2 -> 2014.3283 | AJ2: =EZ2*I2 -> 0 | AK2: =FA2*I2 -> 0 | AL2: =FB2*I2 -> 0 | AM2: =FC2*I2 -> 0 | AN2: =FD2*J2 -> 408.93985 | AO2: =FE2*J2 -> 0 | AP2: =FF2*J2 -> 0 | AQ2: =FG2*J2 -> 0 | AR2: =FH2*K2 -> 29.183 | AS2: =FI2*K2 -> 0 | AT2: =FJ2*K2 -> 0 | AU2: =FK2*K2 -> 0 | AV2: =FL2*K2 -> 0 | AW2: =FM2*L2 -> 26.676337 | AX2: =FN2*L2 -> 0 | AY2: =FO2*L2 -> 0 | AZ2: =FP2*L2 -> 0 | BA2: =FQ2*L2 -> 0 | BB2: =FR2*L2 -> 0 | BC2: =FS2*M2 -> 0 | BD2: =FT2*M2 -> 0 | BE2: =FU2*M2 -> 0 | BF2: =FV2*M2 -> 0 | BG2: =FW2*M2 -> 0 | BH2: =FX2*M2 -> 0 | BI2: =FY2*M2 -> 0 | BJ2: =FZ2*M2 -> 0 | BK2: =GA2*N2 -> 1722.9522 | BL2: =GB2*N2 -> 0 | BM2: =GC2*N2 -> 0 | BN2: =GD2*N2 -> 0 | BO2: =GE2*N2 -> 0 | BP2: Adur | BQ2: 18530.588 | BR2: =BZ2+CX2+EC2+FA2+FU2+GS2+HM2+IK2+JM2+KW2 -> 1619.888 | BS2: 6392.15 | BT2: 12.03 | BU2: 2200.2 | BV2: 7320.89 | BW2: 404.67 | BX2: 1580.9 | BY2: 303.91 | BZ2: 38.988 | CA2: 55.04 | CB2: 0 | CC2: 221.81 | CD2: 0 | CE2: 0 | CF2: 2.22 | CG2: 0 | CH2: 0 | CI2: 0 | CJ2: 2200.2 | CK2: 0 | CL2: 0 | CM2: 0 | CN2: 0 | CO2: 7320.89 | CP2: 0 | CQ2: 0 | CR2: 0 | CS2: 0 | CT2: 403.89 | CU2: 0 | CV2: 0 | CW2: 0.78 | CX2: 1580.9 | CY2: 0 | CZ2: 0 | DA2: 0 | DB2: 0 | DC2: 303.91 | DD2: 0 | DE2: 0 | DF2: 0 | DG2: 38.988 | DH2: 0 | DI2: 0 | DJ2: 0 | DK2: 0 | DL2: 55.04 | DM2: 0 | DN2: 0 | DO2: 0 | DP2: 0 | DQ2: 0 | DR2: 0 | DS2: 0 | DT2: 0 | DU2: 0 | DV2: 0 | DW2: 0 | DX2: 0 | DY2: 0 | DZ2: 221.81 | EA2: 0 | EB2: 0 | EC2: 0 | ED2: 0 | EE2: =CD2/BT2 -> 0 | EF2: =CE2/BT2 -> 0 | EG2: =CF2/BT2 -> 0.18453865 | EH2: =CG2/BT2 -> 0 | EI2: =CH2/BT2 -> 0 | EJ2: =CI2/BU2 -> 0 | EK2: =CJ2/BU2 -> 1 | EL2: =CK2/BU2 -> 0 | EM2: =CL2/BU2 -> 0 | EN2: =CM2/BU2 -> 0 | EO2: =CN2/BU2 -> 0 | EP2: =CO2/BV2 -> 1 | EQ2: =CP2/BV2 -> 0 | ER2: =CQ2/BV2 -> 0 | ES2: =CR2/BV2 -> 0 | ET2: =CS2/BV2 -> 0 | EU2: =CT2/BW2 -> 0.9980725 | EV2: =CU2/BW2 -> 0 | EW2: =CV2/BW2 -> 0 | EX2: =CW2/BW2 -> 0.0019274965 | EY2: =CX2/BX2 -> 1 | EZ2: =CY2/BX2 -> 0 | FA2: =CZ2/BX2 -> 0 | FB2: =DA2/BX2 -> 0 | FC2: =DB2/BX2 -> 0 | FD2: =DC2/BY2 -> 1 | FE2: =DD2/BY2 -> 0 | FF2: =DE2/BY2 -> 0 | FG2: =DF2/BY2 -> 0 | FH2: =DG2/BZ2 -> 1 | FI2: =DH2/BZ2 -> 0 | FJ2: =DI2/BZ2 -> 0 | FK2: =DJ2/BZ2 -> 0 | FL2: =DK2/BZ2 -> 0 | FM2: =DL2/CA2 -> 1 | FN2: =DM2/CA2 -> 0 | FO2: =DN2/CA2 -> 0 | FP2: =DO2/CA2 -> 0 | FQ2: =DP2/CA2 -> 0 | FR2: =DQ2/CA2 -> 0 | FS2: 0 | FT2: 0 | FU2: 0 | FV2: 0 | FW2: 0 | FX2: 0 | FY2: 0 | FZ2: 0 | GA2: =DZ2/CC2 -> 1 | GB2: =EA2/CC2 -> 0 | GC2: =EB2/CC2 -> 0 | GD2: =EC2/CC2 -> 0 | GE2: =ED2/CC2 -> 0
A3: Amber Valley | B3: 38268.119 | C3: =B3-D3 -> 17299.705 | D3: 20968.414 | E3: 0 | F3: 4805.94 | G3: 6927.017 | H3: 1115.6215 | I3: 3606.579 | J3: 796.11788 | K3: 0 | L3: 48.43 | M3: 0 | N3: 0 | O3: =EE3*E3 -> 0 | P3: =EF3*E3 -> 0 | Q3: =EG3*E3 -> 0 | R3: =EH3*E3 -> 0 | S3: =EI3*E3 -> 0 | T3: =EJ3*F3 -> 0 | U3: =EK3*F3 -> 4805.94 | V3: =EL3*F3 -> 0 | W3: =EM3*F3 -> 0 | X3: =EN3*F3 -> 0 | Y3: =EO3*F3 -> 0 | Z3: =EP3*G3 -> 6927.017 | AA3: =EQ3*G3 -> 0 | AB3: =ER3*G3 -> 0 | AC3: =ES3*G3 -> 0 | AD3: =ET3*G3 -> 0 | AE3: =EU3*H3 -> 1115.6215 | AF3: =EV3*H3 -> 0 | AG3: =EW3*H3 -> 0 | AH3: =EX3*H3 -> 0 | AI3: =EY3*I3 -> 3606.579 | AJ3: =EZ3*I3 -> 0 | AK3: =FA3*I3 -> 0 | AL3: =FB3*I3 -> 0 | AM3: =FC3*I3 -> 0 | AN3: =FD3*J3 -> 796.08979 | AO3: =FE3*J3 -> 0.028082131 | AP3: =FF3*J3 -> 0 | AQ3: =FG3*J3 -> 0 | AR3: =FH3*K3 -> 0 | AS3: =FI3*K3 -> 0 | AT3: =FJ3*K3 -> 0 | AU3: =FK3*K3 -> 0 | AV3: =FL3*K3 -> 0 | AW3: =FM3*L3 -> 48.43 | AX3: =FN3*L3 -> 0 | AY3: =FO3*L3 -> 0 | AZ3: =FP3*L3 -> 0 | BA3: =FQ3*L3 -> 0 | BB3: =FR3*L3 -> 0 | BC3: =FS3*M3 -> 0 | BD3: =FT3*M3 -> 0 | BE3: =FU3*M3 -> 0 | BF3: =FV3*M3 -> 0 | BG3: =FW3*M3 -> 0 | BH3: =FX3*M3 -> 0 | BI3: =FY3*M3 -> 0 | BJ3: =FZ3*M3 -> 0 | BK3: =GA3*N3 -> 0 | BL3: =GB3*N3 -> 0 | BM3: =GC3*N3 -> 0 | BN3: =GD3*N3 -> 0 | BO3: =GE3*N3 -> 0 | BP3: Amber Valley | BQ3: 34238.65 | BR3: =BZ3+CX3+EC3+FA3+FU3+GS3+HM3+IK3+JM3+KW3 -> 3606.57 | BS3: 12819.62 | BT3: 0 | BU3: 4805.94 | BV3: 8955.04 | BW3: 1735.08 | BX3: 3606.57 | BY3: 2267.97 | BZ3: 0 | CA3: 48.43 | CB3: 0 | CC3: 0 | CD3: 0 | CE3: 0 | CF3: 0 | CG3: 0 | CH3: 0 | CI3: 0 | CJ3: 4805.94 | CK3: 0 | CL3: 0 | CM3: 0 | CN3: 0 | CO3: 8955.04 | CP3: 0 | CQ3: 0 | CR3: 0 | CS3: 0 | CT3: 1735.08 | CU3: 0 | CV3: 0 | CW3: 0 | CX3: 3606.57 | CY3: 0 | CZ3: 0 | DA3: 0 | DB3: 0 | DC3: 2267.89 | DD3: 0.08 | DE3: 0 | DF3: 0 | DG3: 0 | DH3: 0 | DI3: 0 | DJ3: 0 | DK3: 0 | DL3: 48.43 | DM3: 0 | DN3: 0 | DO3: 0 | DP3: 0 | DQ3: 0 | DR3: 0 | DS3: 0 | DT3: 0 | DU3: 0 | DV3: 0 | DW3: 0 | DX3: 0 | DY3: 0 | DZ3: 0 | EA3: 0 | EB3: 0 | EC3: 0 | ED3: 0 | EE3: 0 | EF3: 0 | EG3: 0 | EH3: 0 | EI3: 0 | EJ3: =CI3/BU3 -> 0 | EK3: =CJ3/BU3 -> 1 | EL3: =CK3/BU3 -> 0 | EM3: =CL3/BU3 -> 0 | EN3: =CM3/BU3 -> 0 | EO3: =CN3/BU3 -> 0 | EP3: =CO3/BV3 -> 1 | EQ3: =CP3/BV3 -> 0 | ER3: =CQ3/BV3 -> 0 | ES3: =CR3/BV3 -> 0 | ET3: =CS3/BV3 -> 0 | EU3: =CT3/BW3 -> 1 | EV3: =CU3/BW3 -> 0 | EW3: =CV3/BW3 -> 0 | EX3: =CW3/BW3 -> 0 | EY3: =CX3/BX3 -> 1 | EZ3: =CY3/BX3 -> 0 | FA3: =CZ3/BX3 -> 0 | FB3: =DA3/BX3 -> 0 | FC3: =DB3/BX3 -> 0 | FD3: =DC3/BY3 -> 0.99996473 | FE3: =DD3/BY3 -> 3.5273835e-05 | FF3: =DE3/BY3 -> 0 | FG3: =DF3/BY3 -> 0 | FH3: 0 | FI3: 0 | FJ3: 0 | FK3: 0 | FL3: 0 | FM3: =DL3/CA3 -> 1 | FN3: =DM3/CA3 -> 0 | FO3: =DN3/CA3 -> 0 | FP3: =DO3/CA3 -> 0 | FQ3: =DP3/CA3 -> 0 | FR3: =DQ3/CA3 -> 0 | FS3: 0 | FT3: 0 | FU3: 0 | FV3: 0 | FW3: 0 | FX3: 0 | FY3: 0 | FZ3: 0 | GA3: 0 | GB3: 0 | GC3: 0 | GD3: 0 | GE3: 0
A4: Arun | B4: 43694.056 | C4: =B4-D4 -> 31914.098 | D4: 11779.958 | E4: 127.9 | F4: 10715.78 | G4: 7281.4886 | H4: 1406.1779 | I4: 6030.0344 | J4: 1144.4683 | K4: 165.176 | L4: 71.074015 | M4: 0 | N4: 4971.9986 | O4: =EE4*E4 -> 0 | P4: =EF4*E4 -> 0 | Q4: =EG4*E4 -> 127.9 | R4: =EH4*E4 -> 0 | S4: =EI4*E4 -> 0 | T4: =EJ4*F4 -> 0 | U4: =EK4*F4 -> 10715.78 | V4: =EL4*F4 -> 0 | W4: =EM4*F4 -> 0 | X4: =EN4*F4 -> 0 | Y4: =EO4*F4 -> 0 | Z4: =EP4*G4 -> 7281.4886 | AA4: =EQ4*G4 -> 0 | AB4: =ER4*G4 -> 0 | AC4: =ES4*G4 -> 0 | AD4: =ET4*G4 -> 0 | AE4: =EU4*H4 -> 1397.1956 | AF4: =EV4*H4 -> 0 | AG4: =EW4*H4 -> 0 | AH4: =EX4*H4 -> 8.982216 | AI4: =EY4*I4 -> 6030.0344 | AJ4: =EZ4*I4 -> 0 | AK4: =FA4*I4 -> 0 | AL4: =FB4*I4 -> 0 | AM4: =FC4*I4 -> 0 | AN4: =FD4*J4 -> 1144.4683 | AO4: =FE4*J4 -> 0 | AP4: =FF4*J4 -> 0 | AQ4: =FG4*J4 -> 0 | AR4: =FH4*K4 -> 165.176 | AS4: =FI4*K4 -> 0 | AT4: =FJ4*K4 -> 0 | AU4: =FK4*K4 -> 0 | AV4: =FL4*K4 -> 0 | AW4: =FM4*L4 -> 71.074015 | AX4: =FN4*L4 -> 0 | AY4: =FO4*L4 -> 0 | AZ4: =FP4*L4 -> 0 | BA4: =FQ4*L4 -> 0 | BB4: =FR4*L4 -> 0 | BC4: =FS4*M4 -> 0 | BD4: =FT4*M4 -> 0 | BE4: =FU4*M4 -> 0 | BF4: =FV4*M4 -> 0 | BG4: =FW4*M4 -> 0 | BH4: =FX4*M4 -> 0 | BI4: =FY4*M4 -> 0 | BJ4: =FZ4*M4 -> 0 | BK4: =GA4*N4 -> 4971.9986 | BL4: =GB4*N4 -> 0 | BM4: =GC4*N4 -> 0 | BN4: =GD4*N4 -> 0 | BO4: =GE4*N4 -> 0 | BP4: Arun | BQ4: 59202.552 | BR4: =BZ4+CX4+EC4+FA4+FU4+GS4+HM4+IK4+JM4+KW4 -> 5041.742 | BS4: 18923.55 | BT4: 134.53 | BU4: 10715.78 | BV4: 21585.74 | BW4: 1235.19 | BX4: 4731.31 | BY4: 830.43 | BZ4: 310.432 | CA4: 144.37 | CB4: 0 | CC4: 591.22 | CD4: 0 | CE4: 0 | CF4: 134.53 | CG4: 0 | CH4: 0 | CI4: 0 | CJ4: 10715.78 | CK4: 0 | CL4: 0 | CM4: 0 | CN4: 0 | CO4: 21585.74 | CP4: 0 | CQ4: 0 | CR4: 0 | CS4: 0 | CT4: 1227.3 | CU4: 0 | CV4: 0 | CW4: 7.89 | CX4: 4731.31 | CY4: 0 | CZ4: 0 | DA4: 0 | DB4: 0 | DC4: 830.43 | DD4: 0 | DE4: 0 | DF4: 0 | DG4: 310.432 | DH4: 0 | DI4: 0 | DJ4: 0 | DK4: 0 | DL4: 144.37 | DM4: 0 | DN4: 0 | DO4: 0 | DP4: 0 | DQ4: 0 | DR4: 0 | DS4: 0 | DT4: 0 | DU4: 0 | DV4: 0 | DW4: 0 | DX4: 0 | DY4: 0 | DZ4: 591.22 | EA4: 0 | EB4: 0 | EC4: 0 | ED4: 0 | EE4: =CD4/BT4 -> 0 | EF4: =CE4/BT4 -> 0 | EG4: =CF4/BT4 -> 1 | EH4: =CG4/BT4 -> 0 | EI4: =CH4/BT4 -> 0 | EJ4: =CI4/BU4 -> 0 | EK4: =CJ4/BU4 -> 1 | EL4: =CK4/BU4 -> 0 | EM4: =CL4/BU4 -> 0 | EN4: =CM4/BU4 -> 0 | EO4: =CN4/BU4 -> 0 | EP4: =CO4/BV4 -> 1 | EQ4: =CP4/BV4 -> 0 | ER4: =CQ4/BV4 -> 0 | ES4: =CR4/BV4 -> 0 | ET4: =CS4/BV4 -> 0 | EU4: =CT4/BW4 -> 0.99361232 | EV4: =CU4/BW4 -> 0 | EW4: =CV4/BW4 -> 0 | EX4: =CW4/BW4 -> 0.0063876812 | EY4: =CX4/BX4 -> 1 | EZ4: =CY4/BX4 -> 0 | FA4: =CZ4/BX4 -> 0 | FB4: =DA4/BX4 -> 0 | FC4: =DB4/BX4 -> 0 | FD4: =DC4/BY4 -> 1 | FE4: =DD4/BY4 -> 0 | FF4: =DE4/BY4 -> 0 | FG4: =DF4/BY4 -> 0 | FH4: =DG4/BZ4 -> 1 | FI4: =DH4/BZ4 -> 0 | FJ4: =DI4/BZ4 -> 0 | FK4: =DJ4/BZ4 -> 0 | FL4: =DK4/BZ4 -> 0 | FM4: =DL4/CA4 -> 1 | FN4: =DM4/CA4 -> 0 | FO4: =DN4/CA4 -> 0 | FP4: =DO4/CA4 -> 0 | FQ4: =DP4/CA4 -> 0 | FR4: =DQ4/CA4 -> 0 | FS4: 0 | FT4: 0 | FU4: 0 | FV4: 0 | FW4: 0 | FX4: 0 | FY4: 0 | FZ4: 0 | GA4: =DZ4/CC4 -> 1 | GB4: =EA4/CC4 -> 0 | GC4: =EB4/CC4 -> 0 | GD4: =EC4/CC4 -> 0 | GE4: =ED4/CC4 -> 0
A5: Ashfield | B5: 37551.04 | C5: =B5-D5 -> 16712.189 | D5: 20838.851 | E5: 0 | F5: 5506.14 | G5: 6248.168 | H5: 1222.0481 | I5: 2976.021 | J5: 759.812 | K5: 0 | L5: 0 | M5: 0 | N5: 0 | O5: =EE5*E5 -> 0 | P5: =EF5*E5 -> 0 | Q5: =EG5*E5 -> 0 | R5: =EH5*E5 -> 0 | S5: =EI5*E5 -> 0 | T5: =EJ5*F5 -> 0 | U5: =EK5*F5 -> 5506.14 | V5: =EL5*F5 -> 0 | W5: =EM5*F5 -> 0 | X5: =EN5*F5 -> 0 | Y5: =EO5*F5 -> 0 | Z5: =EP5*G5 -> 6248.168 | AA5: =EQ5*G5 -> 0 | AB5: =ER5*G5 -> 0 | AC5: =ES5*G5 -> 0 | AD5: =ET5*G5 -> 0 | AE5: =EU5*H5 -> 1222.0481 | AF5: =EV5*H5 -> 0 | AG5: =EW5*H5 -> 0 | AH5: =EX5*H5 -> 0 | AI5: =EY5*I5 -> 2976.021 | AJ5: =EZ5*I5 -> 0 | AK5: =FA5*I5 -> 0 | AL5: =FB5*I5 -> 0 | AM5: =FC5*I5 -> 0 | AN5: =FD5*J5 -> 759.812 | AO5: =FE5*J5 -> 0 | AP5: =FF5*J5 -> 0 | AQ5: =FG5*J5 -> 0 | AR5: =FH5*K5 -> 0 | AS5: =FI5*K5 -> 0 | AT5: =FJ5*K5 -> 0 | AU5: =FK5*K5 -> 0 | AV5: =FL5*K5 -> 0 | AW5: =FM5*L5 -> 0 | AX5: =FN5*L5 -> 0 | AY5: =FO5*L5 -> 0 | AZ5: =FP5*L5 -> 0 | BA5: =FQ5*L5 -> 0 | BB5: =FR5*L5 -> 0 | BC5: =FS5*M5 -> 0 | BD5: =FT5*M5 -> 0 | BE5: =FU5*M5 -> 0 | BF5: =FV5*M5 -> 0 | BG5: =FW5*M5 -> 0 | BH5: =FX5*M5 -> 0 | BI5: =FY5*M5 -> 0 | BJ5: =FZ5*M5 -> 0 | BK5: =GA5*N5 -> 0 | BL5: =GB5*N5 -> 0 | BM5: =GC5*N5 -> 0 | BN5: =GD5*N5 -> 0 | BO5: =GE5*N5 -> 0 | BP5: Ashfield | BQ5: 31992.02 | BR5: =BZ5+CX5+EC5+FA5+FU5+GS5+HM5+IK5+JM5+KW5 -> 2976.03 | BS5: 10568 | BT5: 0 | BU5: 5504.24 | BV5: 10880.34 | BW5: 956.84 | BX5: 2976.03 | BY5: 732.78 | BZ5: 0 | CA5: 0 | CB5: 0 | CC5: 373.79 | CD5: 0 | CE5: 0 | CF5: 0 | CG5: 0 | CH5: 0 | CI5: 0 | CJ5: 5504.24 | CK5: 0 | CL5: 0 | CM5: 0 | CN5: 0 | CO5: 10880.34 | CP5: 0 | CQ5: 0 | CR5: 0 | CS5: 0 | CT5: 956.84 | CU5: 0 | CV5: 0 | CW5: 0 | CX5: 2976.03 | CY5: 0 | CZ5: 0 | DA5: 0 | DB5: 0 | DC5: 732.78 | DD5: 0 | DE5: 0 | DF5: 0 | DG5: 0 | DH5: 0 | DI5: 0 | DJ5: 0 | DK5: 0 | DL5: 0 | DM5: 0 | DN5: 0 | DO5: 0 | DP5: 0 | DQ5: 0 | DR5: 0 | DS5: 0 | DT5: 0 | DU5: 0 | DV5: 0 | DW5: 0 | DX5: 0 | DY5: 0 | DZ5: 373.79 | EA5: 0 | EB5: 0 | EC5: 0 | ED5: 0 | EE5: 0 | EF5: 0 | EG5: 0 | EH5: 0 | EI5: 0 | EJ5: =CI5/BU5 -> 0 | EK5: =CJ5/BU5 -> 1 | EL5: =CK5/BU5 -> 0 | EM5: =CL5/BU5 -> 0 | EN5: =CM5/BU5 -> 0 | EO5: =CN5/BU5 -> 0 | EP5: =CO5/BV5 -> 1 | EQ5: =CP5/BV5 -> 0 | ER5: =CQ5/BV5 -> 0 | ES5: =CR5/BV5 -> 0 | ET5: =CS5/BV5 -> 0 | EU5: =CT5/BW5 -> 1 | EV5: =CU5/BW5 -> 0 | EW5: =CV5/BW5 -> 0 | EX5: =CW5/BW5 -> 0 | EY5: =CX5/BX5 -> 1 | EZ5: =CY5/BX5 -> 0 | FA5: =CZ5/BX5 -> 0 | FB5: =DA5/BX5 -> 0 | FC5: =DB5/BX5 -> 0 | FD5: =DC5/BY5 -> 1 | FE5: =DD5/BY5 -> 0 | FF5: =DE5/BY5 -> 0 | FG5: =DF5/BY5 -> 0 | FH5: 0 | FI5: 0 | FJ5: 0 | FK5: 0 | FL5: 0 | FM5: 0 | FN5: 0 | FO5: 0 | FP5: 0 | FQ5: 0 | FR5: 0 | FS5: 0 | FT5: 0 | FU5: 0 | FV5: 0 | FW5: 0 | FX5: 0 | FY5: 0 | FZ5: 0 | GA5: =DZ5/CC5 -> 1 | GB5: =EA5/CC5 -> 0 | GC5: =EB5/CC5 -> 0 | GD5: =EC5/CC5 -> 0 | GE5: =ED5/CC5 -> 0
A6: Ashford | B6: 33360.89 | C6: =B6-D6 -> 26135.137 | D6: 7225.7534 | E6: 4108.7 | F6: 7092.42 | G6: 7932.4314 | H6: 2426.0499 | I6: 3417.4537 | J6: 1092.6516 | K6: 7.59 | L6: 57.84 | M6: 0 | N6: 0 | O6: =EE6*E6 -> 2096.76 | P6: =EF6*E6 -> 0 | Q6: =EG6*E6 -> 2011.94 | R6: =EH6*E6 -> 0 | S6: =EI6*E6 -> 0 | T6: =EJ6*F6 -> 0 | U6: =EK6*F6 -> 7092.42 | V6: =EL6*F6 -> 0 | W6: =EM6*F6 -> 0 | X6: =EN6*F6 -> 0 | Y6: =EO6*F6 -> 0 | Z6: =EP6*G6 -> 7932.4314 | AA6: =EQ6*G6 -> 0 | AB6: =ER6*G6 -> 0 | AC6: =ES6*G6 -> 0 | AD6: =ET6*G6 -> 0 | AE6: =EU6*H6 -> 2426.0499 | AF6: =EV6*H6 -> 0 | AG6: =EW6*H6 -> 0 | AH6: =EX6*H6 -> 0 | AI6: =EY6*I6 -> 3417.4537 | AJ6: =EZ6*I6 -> 0 | AK6: =FA6*I6 -> 0 | AL6: =FB6*I6 -> 0 | AM6: =FC6*I6 -> 0 | AN6: =FD6*J6 -> 1092.6516 | AO6: =FE6*J6 -> 0 | AP6: =FF6*J6 -> 0 | AQ6: =FG6*J6 -> 0 | AR6: =FH6*K6 -> 7.59 | AS6: =FI6*K6 -> 0 | AT6: =FJ6*K6 -> 0 | AU6: =FK6*K6 -> 0 | AV6: =FL6*K6 -> 0 | AW6: =FM6*L6 -> 57.84 | AX6: =FN6*L6 -> 0 | AY6: =FO6*L6 -> 0 | AZ6: =FP6*L6 -> 0 | BA6: =FQ6*L6 -> 0 | BB6: =FR6*L6 -> 0 | BC6: =FS6*M6 -> 0 | BD6: =FT6*M6 -> 0 | BE6: =FU6*M6 -> 0 | BF6: =FV6*M6 -> 0 | BG6: =FW6*M6 -> 0 | BH6: =FX6*M6 -> 0 | BI6: =FY6*M6 -> 0 | BJ6: =FZ6*M6 -> 0 | BK6: =GA6*N6 -> 0 | BL6: =GB6*N6 -> 0 | BM6: =GC6*N6 -> 0 | BN6: =GD6*N6 -> 0 | BO6: =GE6*N6 -> 0 | BP6: Ashford | BQ6: 75187.3 | BR6: =BZ6+CX6+EC6+FA6+FU6+GS6+HM6+IK6+JM6+KW6 -> 11727.42 | BS6: 16802.7 | BT6: 4108.7 | BU6: 7092.42 | BV6: 11548.79 | BW6: 11556.99 | BX6: 11719.83 | BY6: 11549.61 | BZ6: 7.59 | CA6: 91.28 | CB6: 0 | CC6: 709.39 | CD6: 2096.76 | CE6: 0 | CF6: 2011.94 | CG6: 0 | CH6: 0 | CI6: 0 | CJ6: 7092.42 | CK6: 0 | CL6: 0 | CM6: 0 | CN6: 0 | CO6: 11548.79 | CP6: 0 | CQ6: 0 | CR6: 0 | CS6: 0 | CT6: 11556.99 | CU6: 0 | CV6: 0 | CW6: 0 | CX6: 11719.83 | CY6: 0 | CZ6: 0 | DA6: 0 | DB6: 0 | DC6: 11549.61 | DD6: 0 | DE6: 0 | DF6: 0 | DG6: 7.59 | DH6: 0 | DI6: 0 | DJ6: 0 | DK6: 0 | DL6: 91.28 | DM6: 0 | DN6: 0 | DO6: 0 | DP6: 0 | DQ6: 0 | DR6: 0 | DS6: 0 | DT6: 0 | DU6: 0 | DV6: 0 | DW6: 0 | DX6: 0 | DY6: 0 | DZ6: 709.39 | EA6: 0 | EB6: 0 | EC6: 0 | ED6: 0 | EE6: =CD6/BT6 -> 0.510322 | EF6: =CE6/BT6 -> 0 | EG6: =CF6/BT6 -> 0.489678 | EH6: =CG6/BT6 -> 0 | EI6: =CH6/BT6 -> 0 | EJ6: =CI6/BU6 -> 0 | EK6: =CJ6/BU6 -> 1 | EL6: =CK6/BU6 -> 0 | EM6: =CL6/BU6 -> 0 | EN6: =CM6/BU6 -> 0 | EO6: =CN6/BU6 -> 0 | EP6: =CO6/BV6 -> 1 | EQ6: =CP6/BV6 -> 0 | ER6: =CQ6/BV6 -> 0 | ES6: =CR6/BV6 -> 0 | ET6: =CS6/BV6 -> 0 | EU6: =CT6/BW6 -> 1 | EV6: =CU6/BW6 -> 0 | EW6: =CV6/BW6 -> 0 | EX6: =CW6/BW6 -> 0 | EY6: =CX6/BX6 -> 1 | EZ6: =CY6/BX6 -> 0 | FA6: =CZ6/BX6 -> 0 | FB6: =DA6/BX6 -> 0 | FC6: =DB6/BX6 -> 0 | FD6: =DC6/BY6 -> 1 | FE6: =DD6/BY6 -> 0 | FF6: =DE6/BY6 -> 0 | FG6: =DF6/BY6 -> 0 | FH6: =DG6/BZ6 -> 1 | FI6: =DH6/BZ6 -> 0 | FJ6: =DI6/BZ6 -> 0 | FK6: =DJ6/BZ6 -> 0 | FL6: =DK6/BZ6 -> 0 | FM6: =DL6/CA6 -> 1 | FN6: =DM6/CA6 -> 0 | FO6: =DN6/CA6 -> 0 | FP6: =DO6/CA6 -> 0 | FQ6: =DP6/CA6 -> 0 | FR6: =DQ6/CA6 -> 0 | FS6: 0 | FT6: 0 | FU6: 0 | FV6: 0 | FW6: 0 | FX6: 0 | FY6: 0 | FZ6: 0 | GA6: =DZ6/CC6 -> 1 | GB6: =EA6/CC6 -> 0 | GC6: =EB6/CC6 -> 0 | GD6: =EC6/CC6 -> 0 | GE6: =ED6/CC6 -> 0
A7: Barking and Dagenham | B7: 69857.86 | C7: =B7-D7 -> 21504.061 | D7: 48353.799 | E7: 0 | F7: 2823.25 | G7: 5336.3879 | H7: 2297.9402 | I7: 866.62992 | J7: 1115.7336 | K7: 146.24 | L7: 430.56 | M7: 0 | N7: 8487.3194 | O7: =EE7*E7 -> 0 | P7: =EF7*E7 -> 0 | Q7: =EG7*E7 -> 0 | R7: =EH7*E7 -> 0 | S7: =EI7*E7 -> 0 | T7: =EJ7*F7 -> 0 | U7: =EK7*F7 -> 2823.25 | V7: =EL7*F7 -> 0 | W7: =EM7*F7 -> 0 | X7: =EN7*F7 -> 0 | Y7: =EO7*F7 -> 0 | Z7: =EP7*G7 -> 5336.3879 | AA7: =EQ7*G7 -> 0 | AB7: =ER7*G7 -> 0 | AC7: =ES7*G7 -> 0 | AD7: =ET7*G7 -> 0 | AE7: =EU7*H7 -> 2297.9402 | AF7: =EV7*H7 -> 0 | AG7: =EW7*H7 -> 0 | AH7: =EX7*H7 -> 0 | AI7: =EY7*I7 -> 866.62992 | AJ7: =EZ7*I7 -> 0 | AK7: =FA7*I7 -> 0 | AL7: =FB7*I7 -> 0 | AM7: =FC7*I7 -> 0 | AN7: =FD7*J7 -> 1112.6936 | AO7: =FE7*J7 -> 3.0400309 | AP7: =FF7*J7 -> 0 | AQ7: =FG7*J7 -> 0 | AR7: =FH7*K7 -> 0 | AS7: =FI7*K7 -> 146.24 | AT7: =FJ7*K7 -> 0 | AU7: =FK7*K7 -> 0 | AV7: =FL7*K7 -> 0 | AW7: =FM7*L7 -> 430.56 | AX7: =FN7*L7 -> 0 | AY7: =FO7*L7 -> 0 | AZ7: =FP7*L7 -> 0 | BA7: =FQ7*L7 -> 0 | BB7: =FR7*L7 -> 0 | BC7: =FS7*M7 -> 0 | BD7: =FT7*M7 -> 0 | BE7: =FU7*M7 -> 0 | BF7: =FV7*M7 -> 0 | BG7: =FW7*M7 -> 0 | BH7: =FX7*M7 -> 0 | BI7: =FY7*M7 -> 0 | BJ7: =FZ7*M7 -> 0 | BK7: =GA7*N7 -> 8487.3194 | BL7: =GB7*N7 -> 0 | BM7: =GC7*N7 -> 0 | BN7: =GD7*N7 -> 0 | BO7: =GE7*N7 -> 0 | BP7: Barking and Dagenham | BQ7: 54807.43 | BR7: =BZ7+CX7+EC7+FA7+FU7+GS7+HM7+IK7+JM7+KW7 -> 877.7 | BS7: 30864.63 | BT7: 0 | BU7: 2823.25 | BV7: 5922.22 | BW7: 2030.16 | BX7: 731.58 | BY7: 2903.08 | BZ7: 146.12 | CA7: 2330.51 | CB7: 3276.09 | CC7: 3779.79 | CD7: 0 | CE7: 0 | CF7: 0 | CG7: 0 | CH7: 0 | CI7: 0 | CJ7: 2823.25 | CK7: 0 | CL7: 0 | CM7: 0 | CN7: 0 | CO7: 5922.22 | CP7: 0 | CQ7: 0 | CR7: 0 | CS7: 0 | CT7: 2030.16 | CU7: 0 | CV7: 0 | CW7: 0 | CX7: 731.58 | CY7: 0 | CZ7: 0 | DA7: 0 | DB7: 0 | DC7: 2895.17 | DD7: 7.91 | DE7: 0 | DF7: 0 | DG7: 0 | DH7: 146.12 | DI7: 0 | DJ7: 0 | DK7: 0 | DL7: 2330.51 | DM7: 0 | DN7: 0 | DO7: 0 | DP7: 0 | DQ7: 0 | DR7: 3276.09 | DS7: 0 | DT7: 0 | DU7: 0 | DV7: 0 | DW7: 0 | DX7: 0 | DY7: 0 | DZ7: 3779.79 | EA7: 0 | EB7: 0 | EC7: 0 | ED7: 0 | EE7: 0 | EF7: 0 | EG7: 0 | EH7: 0 | EI7: 0 | EJ7: =CI7/BU7 -> 0 | EK7: =CJ7/BU7 -> 1 | EL7: =CK7/BU7 -> 0 | EM7: =CL7/BU7 -> 0 | EN7: =CM7/BU7 -> 0 | EO7: =CN7/BU7 -> 0 | EP7: =CO7/BV7 -> 1 | EQ7: =CP7/BV7 -> 0 | ER7: =CQ7/BV7 -> 0 | ES7: =CR7/BV7 -> 0 | ET7: =CS7/BV7 -> 0 | EU7: =CT7/BW7 -> 1 | EV7: =CU7/BW7 -> 0 | EW7: =CV7/BW7 -> 0 | EX7: =CW7/BW7 -> 0 | EY7: =CX7/BX7 -> 1 | EZ7: =CY7/BX7 -> 0 | FA7: =CZ7/BX7 -> 0 | FB7: =DA7/BX7 -> 0 | FC7: =DB7/BX7 -> 0 | FD7: =DC7/BY7 -> 0.99727531 | FE7: =DD7/BY7 -> 0.0027246924 | FF7: =DE7/BY7 -> 0 | FG7: =DF7/BY7 -> 0 | FH7: =DG7/BZ7 -> 0 | FI7: =DH7/BZ7 -> 1 | FJ7: =DI7/BZ7 -> 0 | FK7: =DJ7/BZ7 -> 0 | FL7: =DK7/BZ7 -> 0 | FM7: =DL7/CA7 -> 1 | FN7: =DM7/CA7 -> 0 | FO7: =DN7/CA7 -> 0 | FP7: =DO7/CA7 -> 0 | FQ7: =DP7/CA7 -> 0 | FR7: =DQ7/CA7 -> 0 | FS7: =DR7/CB7 -> 1 | FT7: =DS7/CB7 -> 0 | FU7: =DT7/CB7 -> 0 | FV7: =DU7/CB7 -> 0 | FW7: =DV7/CB7 -> 0 | FX7: =DW7/CB7 -> 0 | FY7: =DX7/CB7 -> 0 | FZ7: =DY7/CB7 -> 0 | GA7: =DZ7/CC7 -> 1 | GB7: =EA7/CC7 -> 0 | GC7: =EB7/CC7 -> 0 | GD7: =EC7/CC7 -> 0 | GE7: =ED7/CC7 -> 0
A8: Barnet | B8: 109616.19 | C8: =B8-D8 -> 44272.001 | D8: 65344.191 | E8: 0 | F8: 12025.88 | G8: 18818.7 | H8: 3255.894 | I8: 7322.9704 | J8: 1833.5544 | K8: 572.852 | L8: 442.15 | M8: 0 | N8: 0 | O8: =EE8*E8 -> 0 | P8: =EF8*E8 -> 0 | Q8: =EG8*E8 -> 0 | R8: =EH8*E8 -> 0 | S8: =EI8*E8 -> 0 | T8: =EJ8*F8 -> 0 | U8: =EK8*F8 -> 12025.88 | V8: =EL8*F8 -> 0 | W8: =EM8*F8 -> 0 | X8: =EN8*F8 -> 0 | Y8: =EO8*F8 -> 0 | Z8: =EP8*G8 -> 18579.492 | AA8: =EQ8*G8 -> 239.20802 | AB8: =ER8*G8 -> 0 | AC8: =ES8*G8 -> 0 | AD8: =ET8*G8 -> 0 | AE8: =EU8*H8 -> 3255.894 | AF8: =EV8*H8 -> 0 | AG8: =EW8*H8 -> 0 | AH8: =EX8*H8 -> 0 | AI8: =EY8*I8 -> 7322.9704 | AJ8: =EZ8*I8 -> 0 | AK8: =FA8*I8 -> 0 | AL8: =FB8*I8 -> 0 | AM8: =FC8*I8 -> 0 | AN8: =FD8*J8 -> 1811.198 | AO8: =FE8*J8 -> 22.356397 | AP8: =FF8*J8 -> 0 | AQ8: =FG8*J8 -> 0 | AR8: =FH8*K8 -> 115.69859 | AS8: =FI8*K8 -> 457.15341 | AT8: =FJ8*K8 -> 0 | AU8: =FK8*K8 -> 0 | AV8: =FL8*K8 -> 0 | AW8: =FM8*L8 -> 442.15 | AX8: =FN8*L8 -> 0 | AY8: =FO8*L8 -> 0 | AZ8: =FP8*L8 -> 0 | BA8: =FQ8*L8 -> 0 | BB8: =FR8*L8 -> 0 | BC8: =FS8*M8 -> 0 | BD8: =FT8*M8 -> 0 | BE8: =FU8*M8 -> 0 | BF8: =FV8*M8 -> 0 | BG8: =FW8*M8 -> 0 | BH8: =FX8*M8 -> 0 | BI8: =FY8*M8 -> 0 | BJ8: =FZ8*M8 -> 0 | BK8: =GA8*N8 -> 0 | BL8: =GB8*N8 -> 0 | BM8: =GC8*N8 -> 0 | BN8: =GD8*N8 -> 0 | BO8: =GE8*N8 -> 0 | BP8: Barnet | BQ8: 112192.9 | BR8: =BZ8+CX8+EC8+FA8+FU8+GS8+HM8+IK8+JM8+KW8 -> 10400.193 | BS8: 42052.77 | BT8: 0 | BU8: 11998.62 | BV8: 33861.51 | BW8: 5299.22 | BX8: 9749.04 | BY8: 2445.68 | BZ8: 651.153 | CA8: 884.15 | CB8: 5241.24 | CC8: 9.52 | CD8: 0 | CE8: 0 | CF8: 0 | CG8: 0 | CH8: 0 | CI8: 0 | CJ8: 11998.62 | CK8: 0 | CL8: 0 | CM8: 0 | CN8: 0 | CO8: 33431.09 | CP8: 430.42 | CQ8: 0 | CR8: 0 | CS8: 0 | CT8: 5299.22 | CU8: 0 | CV8: 0 | CW8: 0 | CX8: 9749.04 | CY8: 0 | CZ8: 0 | DA8: 0 | DB8: 0 | DC8: 2415.86 | DD8: 29.82 | DE8: 0 | DF8: 0 | DG8: 131.513 | DH8: 519.64 | DI8: 0 | DJ8: 0 | DK8: 0 | DL8: 884.15 | DM8: 0 | DN8: 0 | DO8: 0 | DP8: 0 | DQ8: 0 | DR8: 3037.49 | DS8: 0 | DT8: 0 | DU8: 0 | DV8: 0 | DW8: 2203.75 | DX8: 0 | DY8: 0 | DZ8: 9.52 | EA8: 0 | EB8: 0 | EC8: 0 | ED8: 0 | EE8: 0 | EF8: 0 | EG8: 0 | EH8: 0 | EI8: 0 | EJ8: =CI8/BU8 -> 0 | EK8: =CJ8/BU8 -> 1 | EL8: =CK8/BU8 -> 0 | EM8: =CL8/BU8 -> 0 | EN8: =CM8/BU8 -> 0 | EO8: =CN8/BU8 -> 0 | EP8: =CO8/BV8 -> 0.98728881 | EQ8: =CP8/BV8 -> 0.012711187 | ER8: =CQ8/BV8 -> 0 | ES8: =CR8/BV8 -> 0 | ET8: =CS8/BV8 -> 0 | EU8: =CT8/BW8 -> 1 | EV8: =CU8/BW8 -> 0 | EW8: =CV8/BW8 -> 0 | EX8: =CW8/BW8 -> 0 | EY8: =CX8/BX8 -> 1 | EZ8: =CY8/BX8 -> 0 | FA8: =CZ8/BX8 -> 0 | FB8: =DA8/BX8 -> 0 | FC8: =DB8/BX8 -> 0 | FD8: =DC8/BY8 -> 0.98780707 | FE8: =DD8/BY8 -> 0.012192928 | FF8: =DE8/BY8 -> 0 | FG8: =DF8/BY8 -> 0 | FH8: =DG8/BZ8 -> 0.20196943 | FI8: =DH8/BZ8 -> 0.79803057 | FJ8: =DI8/BZ8 -> 0 | FK8: =DJ8/BZ8 -> 0 | FL8: =DK8/BZ8 -> 0 | FM8: =DL8/CA8 -> 1 | FN8: =DM8/CA8 -> 0 | FO8: =DN8/CA8 -> 0 | FP8: =DO8/CA8 -> 0 | FQ8: =DP8/CA8 -> 0 | FR8: =DQ8/CA8 -> 0 | FS8: =DR8/CB8 -> 0.57953652 | FT8: =DS8/CB8 -> 0 | FU8: =DT8/CB8 -> 0 | FV8: =DU8/CB8 -> 0 | FW8: =DV8/CB8 -> 0 | FX8: =DW8/CB8 -> 0.42046348 | FY8: =DX8/CB8 -> 0 | FZ8: =DY8/CB8 -> 0 | GA8: =DZ8/CC8 -> 1 | GB8: =EA8/CC8 -> 0 | GC8: =EB8/CC8 -> 0 | GD8: =EC8/CC8 -> 0 | GE8: =ED8/CC8 -> 0
A9: Barnsley | B9: 90053.028 | C9: =B9-D9 -> 46476.433 | D9: 43576.595 | E9: 0 | F9: 14647.86 | G9: 15367.841 | H9: 3924.2557 | I9: 8595.1471 | J9: 2607.2204 | K9: 449.083 | L9: 885.025 | M9: 0 | N9: 0 | O9: =EE9*E9 -> 0 | P9: =EF9*E9 -> 0 | Q9: =EG9*E9 -> 0 | R9: =EH9*E9 -> 0 | S9: =EI9*E9 -> 0 | T9: =EJ9*F9 -> 0 | U9: =EK9*F9 -> 14647.86 | V9: =EL9*F9 -> 0 | W9: =EM9*F9 -> 0 | X9: =EN9*F9 -> 0 | Y9: =EO9*F9 -> 0 | Z9: =EP9*G9 -> 15367.841 | AA9: =EQ9*G9 -> 0 | AB9: =ER9*G9 -> 0 | AC9: =ES9*G9 -> 0 | AD9: =ET9*G9 -> 0 | AE9: =EU9*H9 -> 3924.2557 | AF9: =EV9*H9 -> 0 | AG9: =EW9*H9 -> 0 | AH9: =EX9*H9 -> 0 | AI9: =EY9*I9 -> 8595.1471 | AJ9: =EZ9*I9 -> 0 | AK9: =FA9*I9 -> 0 | AL9: =FB9*I9 -> 0 | AM9: =FC9*I9 -> 0 | AN9: =FD9*J9 -> 2607.2204 | AO9: =FE9*J9 -> 0 | AP9: =FF9*J9 -> 0 | AQ9: =FG9*J9 -> 0 | AR9: =FH9*K9 -> 449.083 | AS9: =FI9*K9 -> 0 | AT9: =FJ9*K9 -> 0 | AU9: =FK9*K9 -> 0 | AV9: =FL9*K9 -> 0 | AW9: =FM9*L9 -> 885.025 | AX9: =FN9*L9 -> 0 | AY9: =FO9*L9 -> 0 | AZ9: =FP9*L9 -> 0 | BA9: =FQ9*L9 -> 0 | BB9: =FR9*L9 -> 0 | BC9: =FS9*M9 -> 0 | BD9: =FT9*M9 -> 0 | BE9: =FU9*M9 -> 0 | BF9: =FV9*M9 -> 0 | BG9: =FW9*M9 -> 0 | BH9: =FX9*M9 -> 0 | BI9: =FY9*M9 -> 0 | BJ9: =FZ9*M9 -> 0 | BK9: =GA9*N9 -> 0 | BL9: =GB9*N9 -> 0 | BM9: =GC9*N9 -> 0 | BN9: =GD9*N9 -> 0 | BO9: =GE9*N9 -> 0 | BP9: Barnsley | BQ9: 251802.39 | BR9: =BZ9+CX9+EC9+FA9+FU9+GS9+HM9+IK9+JM9+KW9 -> 9053.983 | BS9: 202197.79 | BT9: 0 | BU9: 14647.86 | BV9: 8363.894 | BW9: 4576.897 | BX9: 8557.422 | BY9: 10477.084 | BZ9: 496.561 | CA9: 2484.878 | CB9: 0 | CC9: 0 | CD9: 0 | CE9: 0 | CF9: 0 | CG9: 0 | CH9: 0 | CI9: 0 | CJ9: 14647.86 | CK9: 0 | CL9: 0 | CM9: 0 | CN9: 0 | CO9: 8363.894 | CP9: 0 | CQ9: 0 | CR9: 0 | CS9: 0 | CT9: 4576.897 | CU9: 0 | CV9: 0 | CW9: 0 | CX9: 8557.422 | CY9: 0 | CZ9: 0 | DA9: 0 | DB9: 0 | DC9: 10477.084 | DD9: 0 | DE9: 0 | DF9: 0 | DG9: 496.561 | DH9: 0 | DI9: 0 | DJ9: 0 | DK9: 0 | DL9: 2484.878 | DM9: 0 | DN9: 0 | DO9: 0 | DP9: 0 | DQ9: 0 | DR9: 0 | DS9: 0 | DT9: 0 | DU9: 0 | DV9: 0 | DW9: 0 | DX9: 0 | DY9: 0 | DZ9: 0 | EA9: 0 | EB9: 0 | EC9: 0 | ED9: 0 | EE9: 0 | EF9: 0 | EG9: 0 | EH9: 0 | EI9: 0 | EJ9: =CI9/BU9 -> 0 | EK9: =CJ9/BU9 -> 1 | EL9: =CK9/BU9 -> 0 | EM9: =CL9/BU9 -> 0 | EN9: =CM9/BU9 -> 0 | EO9: =CN9/BU9 -> 0 | EP9: =CO9/BV9 -> 1 | EQ9: =CP9/BV9 -> 0 | ER9: =CQ9/BV9 -> 0 | ES9: =CR9/BV9 -> 0 | ET9: =CS9/BV9 -> 0 | EU9: =CT9/BW9 -> 1 | EV9: =CU9/BW9 -> 0 | EW9: =CV9/BW9 -> 0 | EX9: =CW9/BW9 -> 0 | EY9: =CX9/BX9 -> 1 | EZ9: =CY9/BX9 -> 0 | FA9: =CZ9/BX9 -> 0 | FB9: =DA9/BX9 -> 0 | FC9: =DB9/BX9 -> 0 | FD9: =DC9/BY9 -> 1 | FE9: =DD9/BY9 -> 0 | FF9: =DE9/BY9 -> 0 | FG9: =DF9/BY9 -> 0 | FH9: =DG9/BZ9 -> 1 | FI9: =DH9/BZ9 -> 0 | FJ9: =DI9/BZ9 -> 0 | FK9: =DJ9/BZ9 -> 0 | FL9: =DK9/BZ9 -> 0 | FM9: =DL9/CA9 -> 1 | FN9: =DM9/CA9 -> 0 | FO9: =DN9/CA9 -> 0 | FP9: =DO9/CA9 -> 0 | FQ9: =DP9/CA9 -> 0 | FR9: =DQ9/CA9 -> 0 | FS9: 0 | FT9: 0 | FU9: 0 | FV9: 0 | FW9: 0 | FX9: 0 | FY9: 0 | FZ9: 0 | GA9: 0 | GB9: 0 | GC9: 0 | GD9: 0 | GE9: 0
A10: Basildon | B10: 62326.008 | C10: =B10-D10 -> 38074.593 | D10: 24251.415 | E10: 1411.31 | F10: 14464.7 | G10: 9072.4809 | H10: 3243.8933 | I10: 4215.8882 | J10: 1189.3712 | K10: 236.551 | L10: 195.056 | M10: 0 | N10: 4045.3422 | O10: =EE10*E10 -> 0 | P10: =EF10*E10 -> 0 | Q10: =EG10*E10 -> 1411.31 | R10: =EH10*E10 -> 0 | S10: =EI10*E10 -> 0 | T10: =EJ10*F10 -> 13960 | U10: =EK10*F10 -> 504.7 | V10: =EL10*F10 -> 0 | W10: =EM10*F10 -> 0 | X10: =EN10*F10 -> 0 | Y10: =EO10*F10 -> 0 | Z10: =EP10*G10 -> 9072.4809 | AA10: =EQ10*G10 -> 0 | AB10: =ER10*G10 -> 0 | AC10: =ES10*G10 -> 0 | AD10: =ET10*G10 -> 0 | AE10: =EU10*H10 -> 3243.8933 | AF10: =EV10*H10 -> 0 | AG10: =EW10*H10 -> 0 | AH10: =EX10*H10 -> 0 | AI10: =EY10*I10 -> 4215.8882 | AJ10: =EZ10*I10 -> 0 | AK10: =FA10*I10 -> 0 | AL10: =FB10*I10 -> 0 | AM10: =FC10*I10 -> 0 | AN10: =FD10*J10 -> 1189.3712 | AO10: =FE10*J10 -> 0 | AP10: =FF10*J10 -> 0 | AQ10: =FG10*J10 -> 0 | AR10: =FH10*K10 -> 236.551 | AS10: =FI10*K10 -> 0 | AT10: =FJ10*K10 -> 0 | AU10: =FK10*K10 -> 0 | AV10: =FL10*K10 -> 0 | AW10: =FM10*L10 -> 170.38707 | AX10: =FN10*L10 -> 24.668931 | AY10: =FO10*L10 -> 0 | AZ10: =FP10*L10 -> 0 | BA10: =FQ10*L10 -> 0 | BB10: =FR10*L10 -> 0 | BC10: =FS10*M10 -> 0 | BD10: =FT10*M10 -> 0 | BE10: =FU10*M10 -> 0 | BF10: =FV10*M10 -> 0 | BG10: =FW10*M10 -> 0 | BH10: =FX10*M10 -> 0 | BI10: =FY10*M10 -> 0 | BJ10: =FZ10*M10 -> 0 | BK10: =GA10*N10 -> 4045.3422 | BL10: =GB10*N10 -> 0 | BM10: =GC10*N10 -> 0 | BN10: =GD10*N10 -> 0 | BO10: =GE10*N10 -> 0 | BP10: Basildon | BQ10: 69108.983 | BR10: =BZ10+CX10+EC10+FA10+FU10+GS10+HM10+IK10+JM10+KW10 -> 4583.171 | BS10: 26061.955 | BT10: 1411.31 | BU10: 14464.7 | BV10: 14333.238 | BW10: 4683.268 | BX10: 4170.068 | BY10: 917.472 | BZ10: 413.103 | CA10: 308.885 | CB10: 1780.972 | CC10: 564.012 | CD10: 0 | CE10: 0 | CF10: 1411.31 | CG10: 0 | CH10: 0 | CI10: 13960 | CJ10: 504.7 | CK10: 0 | CL10: 0 | CM10: 0 | CN10: 0 | CO10: 14333.238 | CP10: 0 | CQ10: 0 | CR10: 0 | CS10: 0 | CT10: 4683.268 | CU10: 0 | CV10: 0 | CW10: 0 | CX10: 4170.068 | CY10: 0 | CZ10: 0 | DA10: 0 | DB10: 0 | DC10: 917.472 | DD10: 0 | DE10: 0 | DF10: 0 | DG10: 413.103 | DH10: 0 | DI10: 0 | DJ10: 0 | DK10: 0 | DL10: 269.82 | DM10: 39.065 | DN10: 0 | DO10: 0 | DP10: 0 | DQ10: 0 | DR10: 1569.114 | DS10: 0 | DT10: 0 | DU10: 0 | DV10: 211.858 | DW10: 0 | DX10: 0 | DY10: 0 | DZ10: 564.012 | EA10: 0 | EB10: 0 | EC10: 0 | ED10: 0 | EE10: =CD10/BT10 -> 0 | EF10: =CE10/BT10 -> 0 | EG10: =CF10/BT10 -> 1 | EH10: =CG10/BT10 -> 0 | EI10: =CH10/BT10 -> 0 | EJ10: =CI10/BU10 -> 0.96510816 | EK10: =CJ10/BU10 -> 0.03489184 | EL10: =CK10/BU10 -> 0 | EM10: =CL10/BU10 -> 0 | EN10: =CM10/BU10 -> 0 | EO10: =CN10/BU10 -> 0 | EP10: =CO10/BV10 -> 1 | EQ10: =CP10/BV10 -> 0 | ER10: =CQ10/BV10 -> 0 | ES10: =CR10/BV10 -> 0 | ET10: =CS10/BV10 -> 0 | EU10: =CT10/BW10 -> 1 | EV10: =CU10/BW10 -> 0 | EW10: =CV10/BW10 -> 0 | EX10: =CW10/BW10 -> 0 | EY10: =CX10/BX10 -> 1 | EZ10: =CY10/BX10 -> 0 | FA10: =CZ10/BX10 -> 0 | FB10: =DA10/BX10 -> 0 | FC10: =DB10/BX10 -> 0 | FD10: =DC10/BY10 -> 1 | FE10: =DD10/BY10 -> 0 | FF10: =DE10/BY10 -> 0 | FG10: =DF10/BY10 -> 0 | FH10: =DG10/BZ10 -> 1 | FI10: =DH10/BZ10 -> 0 | FJ10: =DI10/BZ10 -> 0 | FK10: =DJ10/BZ10 -> 0 | FL10: =DK10/BZ10 -> 0 | FM10: =DL10/CA10 -> 0.87352898 | FN10: =DM10/CA10 -> 0.12647102 | FO10: =DN10/CA10 -> 0 | FP10: =DO10/CA10 -> 0 | FQ10: =DP10/CA10 -> 0 | FR10: =DQ10/CA10 -> 0 | FS10: =DR10/CB10 -> 0.88104361 | FT10: =DS10/CB10 -> 0 | FU10: =DT10/CB10 -> 0 | FV10: =DU10/CB10 -> 0 | FW10: =DV10/CB10 -> 0.11895639 | FX10: =DW10/CB10 -> 0 | FY10: =DX10/CB10 -> 0 | FZ10: =DY10/CB10 -> 0 | GA10: =DZ10/CC10 -> 1 | GB10: =EA10/CC10 -> 0 | GC10: =EB10/CC10 -> 0 | GD10: =EC10/CC10 -> 0 | GE10: =ED10/CC10 -> 0
A11: Basingstoke and Deane | B11: 51884.76 | C11: =B11-D11 -> 18482.62 | D11: 33402.14 | E11: 0 | F11: 4349.9 | G11: 7409.2688 | H11: 917.87714 | I11: 4603.27 | J11: 780.57431 | K11: 227.32 | L11: 194.41 | M11: 0 | N11: 0 | O11: =EE11*E11 -> 0 | P11: =EF11*E11 -> 0 | Q11: =EG11*E11 -> 0 | R11: =EH11*E11 -> 0 | S11: =EI11*E11 -> 0 | T11: =EJ11*F11 -> 0 | U11: =EK11*F11 -> 4349.9 | V11: =EL11*F11 -> 0 | W11: =EM11*F11 -> 0 | X11: =EN11*F11 -> 0 | Y11: =EO11*F11 -> 0 | Z11: =EP11*G11 -> 7409.2688 | AA11: =EQ11*G11 -> 0 | AB11: =ER11*G11 -> 0 | AC11: =ES11*G11 -> 0 | AD11: =ET11*G11 -> 0 | AE11: =EU11*H11 -> 852.71073 | AF11: =EV11*H11 -> 0 | AG11: =EW11*H11 -> 0 | AH11: =EX11*H11 -> 0 | AI11: =EY11*I11 -> 4603.27 | AJ11: =EZ11*I11 -> 0 | AK11: =FA11*I11 -> 0 | AL11: =FB11*I11 -> 0 | AM11: =FC11*I11 -> 0 | AN11: =FD11*J11 -> 780.57431 | AO11: =FE11*J11 -> 0 | AP11: =FF11*J11 -> 0 | AQ11: =FG11*J11 -> 0 | AR11: =FH11*K11 -> 92.430352 | AS11: =FI11*K11 -> 134.88965 | AT11: =FJ11*K11 -> 0 | AU11: =FK11*K11 -> 0 | AV11: =FL11*K11 -> 0 | AW11: =FM11*L11 -> 10.436707 | AX11: =FN11*L11 -> 183.97329 | AY11: =FO11*L11 -> 0 | AZ11: =FP11*L11 -> 0 | BA11: =FQ11*L11 -> 0 | BB11: =FR11*L11 -> 0 | BC11: =FS11*M11 -> 0 | BD11: =FT11*M11 -> 0 | BE11: =FU11*M11 -> 0 | BF11: =FV11*M11 -> 0 | BG11: =FW11*M11 -> 0 | BH11: =FX11*M11 -> 0 | BI11: =FY11*M11 -> 0 | BJ11: =FZ11*M11 -> 0 | BK11: =GA11*N11 -> 0 | BL11: =GB11*N11 -> 0 | BM11: =GC11*N11 -> 0 | BN11: =GD11*N11 -> 0 | BO11: =GE11*N11 -> 0 | BP11: Basingstoke and Deane | BQ11: 53712.57 | BR11: =BZ11+CX11+EC11+FA11+FU11+GS11+HM11+IK11+JM11+KW11 -> 9792.41 | BS11: 18310.29 | BT11: 0 | BU11: 4349.9 | BV11: 14935.29 | BW11: 1674.44 | BX11: 9206.54 | BY11: 1099.15 | BZ11: 585.87 | CA11: 1836.86 | CB11: 0 | CC11: 1714.23 | CD11: 0 | CE11: 0 | CF11: 0 | CG11: 0 | CH11: 0 | CI11: 0 | CJ11: 4349.9 | CK11: 0 | CL11: 0 | CM11: 0 | CN11: 0 | CO11: 14935.29 | CP11: 0 | CQ11: 0 | CR11: 0 | CS11: 0 | CT11: 1555.56 | CU11: 0 | CV11: 0 | CW11: 0 | CX11: 9206.54 | CY11: 0 | CZ11: 0 | DA11: 0 | DB11: 0 | DC11: 1099.15 | DD11: 0 | DE11: 0 | DF11: 0 | DG11: 238.22 | DH11: 347.65 | DI11: 0 | DJ11: 0 | DK11: 0 | DL11: 98.61 | DM11: 1738.25 | DN11: 0 | DO11: 0 | DP11: 0 | DQ11: 0 | DR11: 0 | DS11: 0 | DT11: 0 | DU11: 0 | DV11: 0 | DW11: 0 | DX11: 0 | DY11: 0 | DZ11: 1018.93 | EA11: 695.3 | EB11: 0 | EC11: 0 | ED11: 0 | EE11: 0 | EF11: 0 | EG11: 0 | EH11: 0 | EI11: 0 | EJ11: =CI11/BU11 -> 0 | EK11: =CJ11/BU11 -> 1 | EL11: =CK11/BU11 -> 0 | EM11: =CL11/BU11 -> 0 | EN11: =CM11/BU11 -> 0 | EO11: =CN11/BU11 -> 0 | EP11: =CO11/BV11 -> 1 | EQ11: =CP11/BV11 -> 0 | ER11: =CQ11/BV11 -> 0 | ES11: =CR11/BV11 -> 0 | ET11: =CS11/BV11 -> 0 | EU11: =CT11/BW11 -> 0.92900313 | EV11: =CU11/BW11 -> 0 | EW11: =CV11/BW11 -> 0 | EX11: =CW11/BW11 -> 0 | EY11: =CX11/BX11 -> 1 | EZ11: =CY11/BX11 -> 0 | FA11: =CZ11/BX11 -> 0 | FB11: =DA11/BX11 -> 0 | FC11: =DB11/BX11 -> 0 | FD11: =DC11/BY11 -> 1 | FE11: =DD11/BY11 -> 0 | FF11: =DE11/BY11 -> 0 | FG11: =DF11/BY11 -> 0 | FH11: =DG11/BZ11 -> 0.40660897 | FI11: =DH11/BZ11 -> 0.59339103 | FJ11: =DI11/BZ11 -> 0 | FK11: =DJ11/BZ11 -> 0 | FL11: =DK11/BZ11 -> 0 | FM11: =DL11/CA11 -> 0.053684004 | FN11: =DM11/CA11 -> 0.946316 | FO11: =DN11/CA11 -> 0 | FP11: =DO11/CA11 -> 0 | FQ11: =DP11/CA11 -> 0 | FR11: =DQ11/CA11 -> 0 | FS11: 0 | FT11: 0 | FU11: 0 | FV11: 0 | FW11: 0 | FX11: 0 | FY11: 0 | FZ11: 0 | GA11: =DZ11/CC11 -> 0.59439515 | GB11: =EA11/CC11 -> 0.40560485 | GC11: =EB11/CC11 -> 0 | GD11: =EC11/CC11 -> 0 | GE11: =ED11/CC11 -> 0
A12: Bassetlaw | B12: 38975.94 | C12: =B12-D12 -> 11892.018 | D12: 27083.922 | E12: 0 | F12: 4062.28 | G12: 5255.7847 | H12: 778.58889 | I12: 1127.84 | J12: 509.58404 | K12: 157.94 | L12: 0 | M12: 0 | N12: 0 | O12: =EE12*E12 -> 0 | P12: =EF12*E12 -> 0 | Q12: =EG12*E12 -> 0 | R12: =EH12*E12 -> 0 | S12: =EI12*E12 -> 0 | T12: =EJ12*F12 -> 0 | U12: =EK12*F12 -> 4062.28 | V12: =EL12*F12 -> 0 | W12: =EM12*F12 -> 0 | X12: =EN12*F12 -> 0 | Y12: =EO12*F12 -> 0 | Z12: =EP12*G12 -> 5255.7847 | AA12: =EQ12*G12 -> 0 | AB12: =ER12*G12 -> 0 | AC12: =ES12*G12 -> 0 | AD12: =ET12*G12 -> 0 | AE12: =EU12*H12 -> 778.58889 | AF12: =EV12*H12 -> 0 | AG12: =EW12*H12 -> 0 | AH12: =EX12*H12 -> 0 | AI12: =EY12*I12 -> 1127.84 | AJ12: =EZ12*I12 -> 0 | AK12: =FA12*I12 -> 0 | AL12: =FB12*I12 -> 0 | AM12: =FC12*I12 -> 0 | AN12: =FD12*J12 -> 509.58404 | AO12: =FE12*J12 -> 0 | AP12: =FF12*J12 -> 0 | AQ12: =FG12*J12 -> 0 | AR12: =FH12*K12 -> 157.94 | AS12: =FI12*K12 -> 0 | AT12: =FJ12*K12 -> 0 | AU12: =FK12*K12 -> 0 | AV12: =FL12*K12 -> 0 | AW12: =FM12*L12 -> 0 | AX12: =FN12*L12 -> 0 | AY12: =FO12*L12 -> 0 | AZ12: =FP12*L12 -> 0 | BA12: =FQ12*L12 -> 0 | BB12: =FR12*L12 -> 0 | BC12: =FS12*M12 -> 0 | BD12: =FT12*M12 -> 0 | BE12: =FU12*M12 -> 0 | BF12: =FV12*M12 -> 0 | BG12: =FW12*M12 -> 0 | BH12: =FX12*M12 -> 0 | BI12: =FY12*M12 -> 0 | BJ12: =FZ12*M12 -> 0 | BK12: =GA12*N12 -> 0 | BL12: =GB12*N12 -> 0 | BM12: =GC12*N12 -> 0 | BN12: =GD12*N12 -> 0 | BO12: =GE12*N12 -> 0 | BP12: Bassetlaw | BQ12: 27655.8 | BR12: =BZ12+CX12+EC12+FA12+FU12+GS12+HM12+IK12+JM12+KW12 -> 3440.74 | BS12: 11240.25 | BT12: 0 | BU12: 4062.28 | BV12: 6895.89 | BW12: 609.62 | BX12: 3282.8 | BY12: 647.31 | BZ12: 157.94 | CA12: 0 | CB12: 0 | CC12: 759.71 | CD12: 0 | CE12: 0 | CF12: 0 | CG12: 0 | CH12: 0 | CI12: 0 | CJ12: 4062.28 | CK12: 0 | CL12: 0 | CM12: 0 | CN12: 0 | CO12: 6895.89 | CP12: 0 | CQ12: 0 | CR12: 0 | CS12: 0 | CT12: 609.62 | CU12: 0 | CV12: 0 | CW12: 0 | CX12: 3282.8 | CY12: 0 | CZ12: 0 | DA12: 0 | DB12: 0 | DC12: 647.31 | DD12: 0 | DE12: 0 | DF12: 0 | DG12: 157.94 | DH12: 0 | DI12: 0 | DJ12: 0 | DK12: 0 | DL12: 0 | DM12: 0 | DN12: 0 | DO12: 0 | DP12: 0 | DQ12: 0 | DR12: 0 | DS12: 0 | DT12: 0 | DU12: 0 | DV12: 0 | DW12: 0 | DX12: 0 | DY12: 0 | DZ12: 759.71 | EA12: 0 | EB12: 0 | EC12: 0 | ED12: 0 | EE12: 0 | EF12: 0 | EG12: 0 | EH12: 0 | EI12: 0 | EJ12: =CI12/BU12 -> 0 | EK12: =CJ12/BU12 -> 1 | EL12: =CK12/BU12 -> 0 | EM12: =CL12/BU12 -> 0 | EN12: =CM12/BU12 -> 0 | EO12: =CN12/BU12 -> 0 | EP12: =CO12/BV12 -> 1 | EQ12: =CP12/BV12 -> 0 | ER12: =CQ12/BV12 -> 0 | ES12: =CR12/BV12 -> 0 | ET12: =CS12/BV12 -> 0 | EU12: =CT12/BW12 -> 1 | EV12: =CU12/BW12 -> 0 | EW12: =CV12/BW12 -> 0 | EX12: =CW12/BW12 -> 0 | EY12: =CX12/BX12 -> 1 | EZ12: =CY12/BX12 -> 0 | FA12: =CZ12/BX12 -> 0 | FB12: =DA12/BX12 -> 0 | FC12: =DB12/BX12 -> 0 | FD12: =DC12/BY12 -> 1 | FE12: =DD12/BY12 -> 0 | FF12: =DE12/BY12 -> 0 | FG12: =DF12/BY12 -> 0 | FH12: =DG12/BZ12 -> 1 | FI12: =DH12/BZ12 -> 0 | FJ12: =DI12/BZ12 -> 0 | FK12: =DJ12/BZ12 -> 0 | FL12: =DK12/BZ12 -> 0 | FM12: 0 | FN12: 0 | FO12: 0 | FP12: 0 | FQ12: 0 | FR12: 0 | FS12: 0 | FT12: 0 | FU12: 0 | FV12: 0 | FW12: 0 | FX12: 0 | FY12: 0 | FZ12: 0 | GA12: =DZ12/CC12 -> 1 | GB12: =EA12/CC12 -> 0 | GC12: =EB12/CC12 -> 0 | GD12: =EC12/CC12 -> 0 | GE12: =ED12/CC12 -> 0
A13: Bath and North East Somerset | B13: 69978.03 | C13: =B13-D13 -> 37308.05 | D13: 32669.98 | E13: 7174.73 | F13: 10512.35 | G13: 8064.16 | H13: 2121.9 | I13: 5979.81 | J13: 2160.44 | K13: 264.35 | L13: 1030.31 | M13: 0 | N13: 0 | O13: =EE13*E13 -> 0 | P13: =EF13*E13 -> 0 | Q13: =EG13*E13 -> 6875.8998 | R13: =EH13*E13 -> 0 | S13: =EI13*E13 -> 0 | T13: =EJ13*F13 -> 0 | U13: =EK13*F13 -> 10512.35 | V13: =EL13*F13 -> 0 | W13: =EM13*F13 -> 0 | X13: =EN13*F13 -> 0 | Y13: =EO13*F13 -> 0 | Z13: =EP13*G13 -> 8064.16 | AA13: =EQ13*G13 -> 0 | AB13: =ER13*G13 -> 0 | AC13: =ES13*G13 -> 0 | AD13: =ET13*G13 -> 0 | AE13: =EU13*H13 -> 2121.9 | AF13: =EV13*H13 -> 0 | AG13: =EW13*H13 -> 0 | AH13: =EX13*H13 -> 0 | AI13: =EY13*I13 -> 5979.81 | AJ13: =EZ13*I13 -> 0 | AK13: =FA13*I13 -> 0 | AL13: =FB13*I13 -> 0 | AM13: =FC13*I13 -> 0 | AN13: =FD13*J13 -> 2157.6473 | AO13: =FE13*J13 -> 2.7927107 | AP13: =FF13*J13 -> 0 | AQ13: =FG13*J13 -> 0 | AR13: =FH13*K13 -> 264.35 | AS13: =FI13*K13 -> 0 | AT13: =FJ13*K13 -> 0 | AU13: =FK13*K13 -> 0 | AV13: =FL13*K13 -> 0 | AW13: =FM13*L13 -> 1030.31 | AX13: =FN13*L13 -> 0 | AY13: =FO13*L13 -> 0 | AZ13: =FP13*L13 -> 0 | BA13: =FQ13*L13 -> 0 | BB13: =FR13*L13 -> 0 | BC13: =FS13*M13 -> 0 | BD13: =FT13*M13 -> 0 | BE13: =FU13*M13 -> 0 | BF13: =FV13*M13 -> 0 | BG13: =FW13*M13 -> 0 | BH13: =FX13*M13 -> 0 | BI13: =FY13*M13 -> 0 | BJ13: =FZ13*M13 -> 0 | BK13: =GA13*N13 -> 0 | BL13: =GB13*N13 -> 0 | BM13: =GC13*N13 -> 0 | BN13: =GD13*N13 -> 0 | BO13: =GE13*N13 -> 0 | BP13: Bath and North East Somerset | BQ13: 140325.16 | BR13: =BZ13+CX13+EC13+FA13+FU13+GS13+HM13+IK13+JM13+KW13 -> 9488 | BS13: 70811.67 | BT13: 7468.84 | BU13: 10512.35 | BV13: 16781.51 | BW13: 2921.73 | BX13: 9066.03 | BY13: 8811.3 | BZ13: 327.93 | CA13: 1325.7 | CB13: 8481.59 | CC13: 3816.51 | CD13: 0 | CE13: 0 | CF13: 7157.76 | CG13: 0 | CH13: 0 | CI13: 0 | CJ13: 10512.35 | CK13: 0 | CL13: 0 | CM13: 0 | CN13: 0 | CO13: 16781.51 | CP13: 0 | CQ13: 0 | CR13: 0 | CS13: 0 | CT13: 2921.73 | CU13: 0 | CV13: 0 | CW13: 0 | CX13: 9066.03 | CY13: 0 | CZ13: 0 | DA13: 0 | DB13: 0 | DC13: 8799.91 | DD13: 11.39 | DE13: 0 | DF13: 0 | DG13: 327.93 | DH13: 0 | DI13: 0 | DJ13: 0 | DK13: 0 | DL13: 1325.7 | DM13: 0 | DN13: 0 | DO13: 0 | DP13: 0 | DQ13: 0 | DR13: 5981.04 | DS13: 0 | DT13: 0 | DU13: 1.79 | DV13: 0 | DW13: 2492.79 | DX13: 0 | DY13: 5.97 | DZ13: 3708.03 | EA13: 0 | EB13: 14.44 | EC13: 94.04 | ED13: 0 | EE13: =CD13/BT13 -> 0 | EF13: =CE13/BT13 -> 0 | EG13: =CF13/BT13 -> 0.95834962 | EH13: =CG13/BT13 -> 0 | EI13: =CH13/BT13 -> 0 | EJ13: =CI13/BU13 -> 0 | EK13: =CJ13/BU13 -> 1 | EL13: =CK13/BU13 -> 0 | EM13: =CL13/BU13 -> 0 | EN13: =CM13/BU13 -> 0 | EO13: =CN13/BU13 -> 0 | EP13: =CO13/BV13 -> 1 | EQ13: =CP13/BV13 -> 0 | ER13: =CQ13/BV13 -> 0 | ES13: =CR13/BV13 -> 0 | ET13: =CS13/BV13 -> 0 | EU13: =CT13/BW13 -> 1 | EV13: =CU13/BW13 -> 0 | EW13: =CV13/BW13 -> 0 | EX13: =CW13/BW13 -> 0 | EY13: =CX13/BX13 -> 1 | EZ13: =CY13/BX13 -> 0 | FA13: =CZ13/BX13 -> 0 | FB13: =DA13/BX13 -> 0 | FC13: =DB13/BX13 -> 0 | FD13: =DC13/BY13 -> 0.99870734 | FE13: =DD13/BY13 -> 0.0012926583 | FF13: =DE13/BY13 -> 0 | FG13: =DF13/BY13 -> 0 | FH13: =DG13/BZ13 -> 1 | FI13: =DH13/BZ13 -> 0 | FJ13: =DI13/BZ13 -> 0 | FK13: =DJ13/BZ13 -> 0 | FL13: =DK13/BZ13 -> 0 | FM13: =DL13/CA13 -> 1 | FN13: =DM13/CA13 -> 0 | FO13: =DN13/CA13 -> 0 | FP13: =DO13/CA13 -> 0 | FQ13: =DP13/CA13 -> 0 | FR13: =DQ13/CA13 -> 0 | FS13: =DR13/CB13 -> 0.7051791 | FT13: =DS13/CB13 -> 0 | FU13: =DT13/CB13 -> 0 | FV13: =DU13/CB13 -> 0.00021104533 | FW13: =DV13/CB13 -> 0 | FX13: =DW13/CB13 -> 0.29390598 | FY13: =DX13/CB13 -> 0 | FZ13: =DY13/CB13 -> 0.00070387746 | GA13: =DZ13/CC13 -> 0.97157613 | GB13: =EA13/CC13 -> 0 | GC13: =EB13/CC13 -> 0.0037835614 | GD13: =EC13/CC13 -> 0.024640313 | GE13: =ED13/CC13 -> 0
A14: Bedford | B14: 60892.15 | C14: =B14-D14 -> 27368.317 | D14: 33523.833 | E14: 0 | F14: 11354.52 | G14: 8190.3983 | H14: 1718.201 | I14: 3421.8756 | J14: 1661.4424 | K14: 223.58 | L14: 798.3 | M14: 0 | N14: 0 | O14: =EE14*E14 -> 0 | P14: =EF14*E14 -> 0 | Q14: =EG14*E14 -> 0 | R14: =EH14*E14 -> 0 | S14: =EI14*E14 -> 0 | T14: =EJ14*F14 -> 0 | U14: =EK14*F14 -> 11354.52 | V14: =EL14*F14 -> 0 | W14: =EM14*F14 -> 0 | X14: =EN14*F14 -> 0 | Y14: =EO14*F14 -> 0 | Z14: =EP14*G14 -> 8190.3983 | AA14: =EQ14*G14 -> 0 | AB14: =ER14*G14 -> 0 | AC14: =ES14*G14 -> 0 | AD14: =ET14*G14 -> 0 | AE14: =EU14*H14 -> 1677.908 | AF14: =EV14*H14 -> 40.29298 | AG14: =EW14*H14 -> 0 | AH14: =EX14*H14 -> 0 | AI14: =EY14*I14 -> 3421.8756 | AJ14: =EZ14*I14 -> 0 | AK14: =FA14*I14 -> 0 | AL14: =FB14*I14 -> 0 | AM14: =FC14*I14 -> 0 | AN14: =FD14*J14 -> 1655.8433 | AO14: =FE14*J14 -> 5.5990964 | AP14: =FF14*J14 -> 0 | AQ14: =FG14*J14 -> 0 | AR14: =FH14*K14 -> 219.36489 | AS14: =FI14*K14 -> 4.2151094 | AT14: =FJ14*K14 -> 0 | AU14: =FK14*K14 -> 0 | AV14: =FL14*K14 -> 0 | AW14: =FM14*L14 -> 786.68469 | AX14: =FN14*L14 -> 11.615306 | AY14: =FO14*L14 -> 0 | AZ14: =FP14*L14 -> 0 | BA14: =FQ14*L14 -> 0 | BB14: =FR14*L14 -> 0 | BC14: =FS14*M14 -> 0 | BD14: =FT14*M14 -> 0 | BE14: =FU14*M14 -> 0 | BF14: =FV14*M14 -> 0 | BG14: =FW14*M14 -> 0 | BH14: =FX14*M14 -> 0 | BI14: =FY14*M14 -> 0 | BJ14: =FZ14*M14 -> 0 | BK14: =GA14*N14 -> 0 | BL14: =GB14*N14 -> 0 | BM14: =GC14*N14 -> 0 | BN14: =GD14*N14 -> 0 | BO14: =GE14*N14 -> 0 | BP14: Bedford | BQ14: 145003.18 | BR14: =BZ14+CX14+EC14+FA14+FU14+GS14+HM14+IK14+JM14+KW14 -> 5650.104 | BS14: 111095.19 | BT14: 0 | BU14: 11817.08 | BV14: 7195.86 | BW14: 2169.66 | BX14: 5415.55 | BY14: 1439.16 | BZ14: 234.554 | CA14: 743.64 | CB14: 4225.56 | CC14: 666.92 | CD14: 0 | CE14: 0 | CF14: 0 | CG14: 0 | CH14: 0 | CI14: 0 | CJ14: 11817.08 | CK14: 0 | CL14: 0 | CM14: 0 | CN14: 0 | CO14: 7195.86 | CP14: 0 | CQ14: 0 | CR14: 0 | CS14: 0 | CT14: 2118.78 | CU14: 50.88 | CV14: 0 | CW14: 0 | CX14: 5415.55 | CY14: 0 | CZ14: 0 | DA14: 0 | DB14: 0 | DC14: 1434.31 | DD14: 4.85 | DE14: 0 | DF14: 0 | DG14: 230.132 | DH14: 4.422 | DI14: 0 | DJ14: 0 | DK14: 0 | DL14: 732.82 | DM14: 10.82 | DN14: 0 | DO14: 0 | DP14: 0 | DQ14: 0 | DR14: 2118.74 | DS14: 0 | DT14: 0 | DU14: 0 | DV14: 0 | DW14: 2106.82 | DX14: 0 | DY14: 0 | DZ14: 646.39 | EA14: 20.53 | EB14: 0 | EC14: 0 | ED14: 0 | EE14: 0 | EF14: 0 | EG14: 0 | EH14: 0 | EI14: 0 | EJ14: =CI14/BU14 -> 0 | EK14: =CJ14/BU14 -> 1 | EL14: =CK14/BU14 -> 0 | EM14: =CL14/BU14 -> 0 | EN14: =CM14/BU14 -> 0 | EO14: =CN14/BU14 -> 0 | EP14: =CO14/BV14 -> 1 | EQ14: =CP14/BV14 -> 0 | ER14: =CQ14/BV14 -> 0 | ES14: =CR14/BV14 -> 0 | ET14: =CS14/BV14 -> 0 | EU14: =CT14/BW14 -> 0.97654932 | EV14: =CU14/BW14 -> 0.023450679 | EW14: =CV14/BW14 -> 0 | EX14: =CW14/BW14 -> 0 | EY14: =CX14/BX14 -> 1 | EZ14: =CY14/BX14 -> 0 | FA14: =CZ14/BX14 -> 0 | FB14: =DA14/BX14 -> 0 | FC14: =DB14/BX14 -> 0 | FD14: =DC14/BY14 -> 0.99662998 | FE14: =DD14/BY14 -> 0.0033700214 | FF14: =DE14/BY14 -> 0 | FG14: =DF14/BY14 -> 0 | FH14: =DG14/BZ14 -> 0.9811472 | FI14: =DH14/BZ14 -> 0.018852801 | FJ14: =DI14/BZ14 -> 0 | FK14: =DJ14/BZ14 -> 0 | FL14: =DK14/BZ14 -> 0 | FM14: =DL14/CA14 -> 0.98544995 | FN14: =DM14/CA14 -> 0.014550051 | FO14: =DN14/CA14 -> 0 | FP14: =DO14/CA14 -> 0 | FQ14: =DP14/CA14 -> 0 | FR14: =DQ14/CA14 -> 0 | FS14: =DR14/CB14 -> 0.50141046 | FT14: =DS14/CB14 -> 0 | FU14: =DT14/CB14 -> 0 | FV14: =DU14/CB14 -> 0 | FW14: =DV14/CB14 -> 0 | FX14: =DW14/CB14 -> 0.49858954 | FY14: =DX14/CB14 -> 0 | FZ14: =DY14/CB14 -> 0 | GA14: =DZ14/CC14 -> 0.9692167 | GB14: =EA14/CC14 -> 0.030783302 | GC14: =EB14/CC14 -> 0 | GD14: =EC14/CC14 -> 0 | GE14: =ED14/CC14 -> 0
A15: Bexley | B15: 74128.09 | C15: =B15-D15 -> 37672.218 | D15: 36455.872 | E15: 4861.01 | F15: 11015.87 | G15: 7432.2344 | H15: 2835.6228 | I15: 8272.725 | J15: 2062.416 | K15: 509.96 | L15: 682.38 | M15: 0 | N15: 0 | O15: =EE15*E15 -> 0 | P15: =EF15*E15 -> 0 | Q15: =EG15*E15 -> 4861.01 | R15: =EH15*E15 -> 0 | S15: =EI15*E15 -> 0 | T15: =EJ15*F15 -> 0 | U15: =EK15*F15 -> 11015.87 | V15: =EL15*F15 -> 0 | W15: =EM15*F15 -> 0 | X15: =EN15*F15 -> 0 | Y15: =EO15*F15 -> 0 | Z15: =EP15*G15 -> 7432.2344 | AA15: =EQ15*G15 -> 0 | AB15: =ER15*G15 -> 0 | AC15: =ES15*G15 -> 0 | AD15: =ET15*G15 -> 0 | AE15: =EU15*H15 -> 2835.6228 | AF15: =EV15*H15 -> 0 | AG15: =EW15*H15 -> 0 | AH15: =EX15*H15 -> 0 | AI15: =EY15*I15 -> 8272.725 | AJ15: =EZ15*I15 -> 0 | AK15: =FA15*I15 -> 0 | AL15: =FB15*I15 -> 0 | AM15: =FC15*I15 -> 0 | AN15: =FD15*J15 -> 2061.1221 | AO15: =FE15*J15 -> 1.2939283 | AP15: =FF15*J15 -> 0 | AQ15: =FG15*J15 -> 0 | AR15: =FH15*K15 -> 509.96 | AS15: =FI15*K15 -> 0 | AT15: =FJ15*K15 -> 0 | AU15: =FK15*K15 -> 0 | AV15: =FL15*K15 -> 0 | AW15: =FM15*L15 -> 682.38 | AX15: =FN15*L15 -> 0 | AY15: =FO15*L15 -> 0 | AZ15: =FP15*L15 -> 0 | BA15: =FQ15*L15 -> 0 | BB15: =FR15*L15 -> 0 | BC15: =FS15*M15 -> 0 | BD15: =FT15*M15 -> 0 | BE15: =FU15*M15 -> 0 | BF15: =FV15*M15 -> 0 | BG15: =FW15*M15 -> 0 | BH15: =FX15*M15 -> 0 | BI15: =FY15*M15 -> 0 | BJ15: =FZ15*M15 -> 0 | BK15: =GA15*N15 -> 0 | BL15: =GB15*N15 -> 0 | BM15: =GC15*N15 -> 0 | BN15: =GD15*N15 -> 0 | BO15: =GE15*N15 -> 0 | BP15: Bexley | BQ15: 192268.11 | BR15: =BZ15+CX15+EC15+FA15+FU15+GS15+HM15+IK15+JM15+KW15 -> 7803.24 | BS15: 140672.87 | BT15: 4861.01 | BU15: 11167.01 | BV15: 8017.92 | BW15: 2325.12 | BX15: 6504.91 | BY15: 12687.59 | BZ15: 1298.33 | CA15: 1171.34 | CB15: 2255.86 | CC15: 1306.15 | CD15: 0 | CE15: 0 | CF15: 4861.01 | CG15: 0 | CH15: 0 | CI15: 0 | CJ15: 11167.01 | CK15: 0 | CL15: 0 | CM15: 0 | CN15: 0 | CO15: 8017.92 | CP15: 0 | CQ15: 0 | CR15: 0 | CS15: 0 | CT15: 2325.12 | CU15: 0 | CV15: 0 | CW15: 0 | CX15: 6504.91 | CY15: 0 | CZ15: 0 | DA15: 0 | DB15: 0 | DC15: 12679.63 | DD15: 7.96 | DE15: 0 | DF15: 0 | DG15: 1298.33 | DH15: 0 | DI15: 0 | DJ15: 0 | DK15: 0 | DL15: 1171.34 | DM15: 0 | DN15: 0 | DO15: 0 | DP15: 0 | DQ15: 0 | DR15: 1515.83 | DS15: 0 | DT15: 0 | DU15: 47.84 | DV15: 0 | DW15: 692.19 | DX15: 0 | DY15: 0 | DZ15: 1289.84 | EA15: 16.31 | EB15: 0 | EC15: 0 | ED15: 0 | EE15: =CD15/BT15 -> 0 | EF15: =CE15/BT15 -> 0 | EG15: =CF15/BT15 -> 1 | EH15: =CG15/BT15 -> 0 | EI15: =CH15/BT15 -> 0 | EJ15: =CI15/BU15 -> 0 | EK15: =CJ15/BU15 -> 1 | EL15: =CK15/BU15 -> 0 | EM15: =CL15/BU15 -> 0 | EN15: =CM15/BU15 -> 0 | EO15: =CN15/BU15 -> 0 | EP15: =CO15/BV15 -> 1 | EQ15: =CP15/BV15 -> 0 | ER15: =CQ15/BV15 -> 0 | ES15: =CR15/BV15 -> 0 | ET15: =CS15/BV15 -> 0 | EU15: =CT15/BW15 -> 1 | EV15: =CU15/BW15 -> 0 | EW15: =CV15/BW15 -> 0 | EX15: =CW15/BW15 -> 0 | EY15: =CX15/BX15 -> 1 | EZ15: =CY15/BX15 -> 0 | FA15: =CZ15/BX15 -> 0 | FB15: =DA15/BX15 -> 0 | FC15: =DB15/BX15 -> 0 | FD15: =DC15/BY15 -> 0.99937262 | FE15: =DD15/BY15 -> 0.00062738471 | FF15: =DE15/BY15 -> 0 | FG15: =DF15/BY15 -> 0 | FH15: =DG15/BZ15 -> 1 | FI15: =DH15/BZ15 -> 0 | FJ15: =DI15/BZ15 -> 0 | FK15: =DJ15/BZ15 -> 0 | FL15: =DK15/BZ15 -> 0 | FM15: =DL15/CA15 -> 1 | FN15: =DM15/CA15 -> 0 | FO15: =DN15/CA15 -> 0 | FP15: =DO15/CA15 -> 0 | FQ15: =DP15/CA15 -> 0 | FR15: =DQ15/CA15 -> 0 | FS15: =DR15/CB15 -> 0.67195216 | FT15: =DS15/CB15 -> 0 | FU15: =DT15/CB15 -> 0 | FV15: =DU15/CB15 -> 0.02120699 | FW15: =DV15/CB15 -> 0 | FX15: =DW15/CB15 -> 0.30684085 | FY15: =DX15/CB15 -> 0 | FZ15: =DY15/CB15 -> 0 | GA15: =DZ15/CC15 -> 0.98751292 | GB15: =EA15/CC15 -> 0.01248708 | GC15: =EB15/CC15 -> 0 | GD15: =EC15/CC15 -> 0 | GE15: =ED15/CC15 -> 0
A16: Birmingham | B16: 352425.37 | C16: =B16-D16 -> 102561.15 | D16: 249864.22 | E16: 0 | F16: 25937.7 | G16: 17439.27 | H16: 8171.7663 | I16: 16835.13 | J16: 5785.014 | K16: 629.26 | L16: 1969.16 | M16: 0 | N16: 25793.851 | O16: =EE16*E16 -> 0 | P16: =EF16*E16 -> 0 | Q16: =EG16*E16 -> 0 | R16: =EH16*E16 -> 0 | S16: =EI16*E16 -> 0 | T16: =EJ16*F16 -> 0 | U16: =EK16*F16 -> 25937.7 | V16: =EL16*F16 -> 0 | W16: =EM16*F16 -> 0 | X16: =EN16*F16 -> 0 | Y16: =EO16*F16 -> 0 | Z16: =EP16*G16 -> 17439.27 | AA16: =EQ16*G16 -> 0 | AB16: =ER16*G16 -> 0 | AC16: =ES16*G16 -> 0 | AD16: =ET16*G16 -> 0 | AE16: =EU16*H16 -> 8171.7663 | AF16: =EV16*H16 -> 0 | AG16: =EW16*H16 -> 0 | AH16: =EX16*H16 -> 0 | AI16: =EY16*I16 -> 16835.13 | AJ16: =EZ16*I16 -> 0 | AK16: =FA16*I16 -> 0 | AL16: =FB16*I16 -> 0 | AM16: =FC16*I16 -> 0 | AN16: =FD16*J16 -> 5785.014 | AO16: =FE16*J16 -> 0 | AP16: =FF16*J16 -> 0 | AQ16: =FG16*J16 -> 0 | AR16: =FH16*K16 -> 629.26 | AS16: =FI16*K16 -> 0 | AT16: =FJ16*K16 -> 0 | AU16: =FK16*K16 -> 0 | AV16: =FL16*K16 -> 0 | AW16: =FM16*L16 -> 1800.2533 | AX16: =FN16*L16 -> 0 | AY16: =FO16*L16 -> 0 | AZ16: =FP16*L16 -> 0 | BA16: =FQ16*L16 -> 0 | BB16: =FR16*L16 -> 168.90672 | BC16: =FS16*M16 -> 0 | BD16: =FT16*M16 -> 0 | BE16: =FU16*M16 -> 0 | BF16: =FV16*M16 -> 0 | BG16: =FW16*M16 -> 0 | BH16: =FX16*M16 -> 0 | BI16: =FY16*M16 -> 0 | BJ16: =FZ16*M16 -> 0 | BK16: =GA16*N16 -> 24682.808 | BL16: =GB16*N16 -> 1111.0434 | BM16: =GC16*N16 -> 0 | BN16: =GD16*N16 -> 0 | BO16: =GE16*N16 -> 0 | BP16: Birmingham | BQ16: 905545.04 | BR16: =BZ16+CX16+EC16+FA16+FU16+GS16+HM16+IK16+JM16+KW16 -> 15468.44 | BS16: 771352.24 | BT16: 0 | BU16: 25937.7 | BV16: 35377.04 | BW16: 6997.4 | BX16: 13443.35 | BY16: 17300.53 | BZ16: 2025.09 | CA16: 6075.94 | CB16: 19103.58 | CC16: 7932.17 | CD16: 0 | CE16: 0 | CF16: 0 | CG16: 0 | CH16: 0 | CI16: 0 | CJ16: 25937.7 | CK16: 0 | CL16: 0 | CM16: 0 | CN16: 0 | CO16: 35377.04 | CP16: 0 | CQ16: 0 | CR16: 0 | CS16: 0 | CT16: 6997.4 | CU16: 0 | CV16: 0 | CW16: 0 | CX16: 13443.35 | CY16: 0 | CZ16: 0 | DA16: 0 | DB16: 0 | DC16: 17300.53 | DD16: 0 | DE16: 0 | DF16: 0 | DG16: 2025.09 | DH16: 0 | DI16: 0 | DJ16: 0 | DK16: 0 | DL16: 5554.77 | DM16: 0 | DN16: 0 | DO16: 0 | DP16: 0 | DQ16: 521.17 | DR16: 19103.58 | DS16: 0 | DT16: 0 | DU16: 0 | DV16: 0 | DW16: 0 | DX16: 0 | DY16: 0 | DZ16: 7590.5 | EA16: 341.67 | EB16: 0 | EC16: 0 | ED16: 0 | EE16: 0 | EF16: 0 | EG16: 0 | EH16: 0 | EI16: 0 | EJ16: =CI16/BU16 -> 0 | EK16: =CJ16/BU16 -> 1 | EL16: =CK16/BU16 -> 0 | EM16: =CL16/BU16 -> 0 | EN16: =CM16/BU16 -> 0 | EO16: =CN16/BU16 -> 0 | EP16: =CO16/BV16 -> 1 | EQ16: =CP16/BV16 -> 0 | ER16: =CQ16/BV16 -> 0 | ES16: =CR16/BV16 -> 0 | ET16: =CS16/BV16 -> 0 | EU16: =CT16/BW16 -> 1 | EV16: =CU16/BW16 -> 0 | EW16: =CV16/BW16 -> 0 | EX16: =CW16/BW16 -> 0 | EY16: =CX16/BX16 -> 1 | EZ16: =CY16/BX16 -> 0 | FA16: =CZ16/BX16 -> 0 | FB16: =DA16/BX16 -> 0 | FC16: =DB16/BX16 -> 0 | FD16: =DC16/BY16 -> 1 | FE16: =DD16/BY16 -> 0 | FF16: =DE16/BY16 -> 0 | FG16: =DF16/BY16 -> 0 | FH16: =DG16/BZ16 -> 1 | FI16: =DH16/BZ16 -> 0 | FJ16: =DI16/BZ16 -> 0 | FK16: =DJ16/BZ16 -> 0 | FL16: =DK16/BZ16 -> 0 | FM16: =DL16/CA16 -> 0.91422397 | FN16: =DM16/CA16 -> 0 | FO16: =DN16/CA16 -> 0 | FP16: =DO16/CA16 -> 0 | FQ16: =DP16/CA16 -> 0 | FR16: =DQ16/CA16 -> 0.085776028 | FS16: =DR16/CB16 -> 1 | FT16: =DS16/CB16 -> 0 | FU16: =DT16/CB16 -> 0 | FV16: =DU16/CB16 -> 0 | FW16: =DV16/CB16 -> 0 | FX16: =DW16/CB16 -> 0 | FY16: =DX16/CB16 -> 0 | FZ16: =DY16/CB16 -> 0 | GA16: =DZ16/CC16 -> 0.95692604 | GB16: =EA16/CC16 -> 0.043073963 | GC16: =EB16/CC16 -> 0 | GD16: =EC16/CC16 -> 0 | GE16: =ED16/CC16 -> 0
A17: Blaby | B17: 25481.105 | C17: =B17-D17 -> 16172.84 | D17: 9308.2653 | E17: 0 | F17: 5889.82 | G17: 4665.4412 | H17: 1232.1978 | I17: 3635.6073 | J17: 613.73344 | K17: 105.85 | L17: 30.19 | M17: 0 | N17: 0 | O17: =EE17*E17 -> 0 | P17: =EF17*E17 -> 0 | Q17: =EG17*E17 -> 0 | R17: =EH17*E17 -> 0 | S17: =EI17*E17 -> 0 | T17: =EJ17*F17 -> 0 | U17: =EK17*F17 -> 5889.82 | V17: =EL17*F17 -> 0 | W17: =EM17*F17 -> 0 | X17: =EN17*F17 -> 0 | Y17: =EO17*F17 -> 0 | Z17: =EP17*G17 -> 4665.4412 | AA17: =EQ17*G17 -> 0 | AB17: =ER17*G17 -> 0 | AC17: =ES17*G17 -> 0 | AD17: =ET17*G17 -> 0 | AE17: =EU17*H17 -> 1232.1978 | AF17: =EV17*H17 -> 0 | AG17: =EW17*H17 -> 0 | AH17: =EX17*H17 -> 0 | AI17: =EY17*I17 -> 3635.6073 | AJ17: =EZ17*I17 -> 0 | AK17: =FA17*I17 -> 0 | AL17: =FB17*I17 -> 0 | AM17: =FC17*I17 -> 0 | AN17: =FD17*J17 -> 613.73344 | AO17: =FE17*J17 -> 0 | AP17: =FF17*J17 -> 0 | AQ17: =FG17*J17 -> 0 | AR17: =FH17*K17 -> 82.202729 | AS17: =FI17*K17 -> 23.647271 | AT17: =FJ17*K17 -> 0 | AU17: =FK17*K17 -> 0 | AV17: =FL17*K17 -> 0 | AW17: =FM17*L17 -> 30.19 | AX17: =FN17*L17 -> 0 | AY17: =FO17*L17 -> 0 | AZ17: =FP17*L17 -> 0 | BA17: =FQ17*L17 -> 0 | BB17: =FR17*L17 -> 0 | BC17: =FS17*M17 -> 0 | BD17: =FT17*M17 -> 0 | BE17: =FU17*M17 -> 0 | BF17: =FV17*M17 -> 0 | BG17: =FW17*M17 -> 0 | BH17: =FX17*M17 -> 0 | BI17: =FY17*M17 -> 0 | BJ17: =FZ17*M17 -> 0 | BK17: =GA17*N17 -> 0 | BL17: =GB17*N17 -> 0 | BM17: =GC17*N17 -> 0 | BN17: =GD17*N17 -> 0 | BO17: =GE17*N17 -> 0 | BP17: Blaby | BQ17: 26638.082 | BR17: =BZ17+CX17+EC17+FA17+FU17+GS17+HM17+IK17+JM17+KW17 -> 3006.327 | BS17: 12284.571 | BT17: 0 | BU17: 5946.43 | BV17: 3652.95 | BW17: 964.787 | BX17: 2845.027 | BY17: 428.29 | BZ17: 161.3 | CA17: 30.19 | CB17: 0 | CC17: 324.537 | CD17: 0 | CE17: 0 | CF17: 0 | CG17: 0 | CH17: 0 | CI17: 0 | CJ17: 5946.43 | CK17: 0 | CL17: 0 | CM17: 0 | CN17: 0 | CO17: 3652.95 | CP17: 0 | CQ17: 0 | CR17: 0 | CS17: 0 | CT17: 964.787 | CU17: 0 | CV17: 0 | CW17: 0 | CX17: 2845.027 | CY17: 0 | CZ17: 0 | DA17: 0 | DB17: 0 | DC17: 428.29 | DD17: 0 | DE17: 0 | DF17: 0 | DG17: 125.265 | DH17: 36.035 | DI17: 0 | DJ17: 0 | DK17: 0 | DL17: 30.19 | DM17: 0 | DN17: 0 | DO17: 0 | DP17: 0 | DQ17: 0 | DR17: 0 | DS17: 0 | DT17: 0 | DU17: 0 | DV17: 0 | DW17: 0 | DX17: 0 | DY17: 0 | DZ17: 238.024 | EA17: 86.513 | EB17: 0 | EC17: 0 | ED17: 0 | EE17: 0 | EF17: 0 | EG17: 0 | EH17: 0 | EI17: 0 | EJ17: =CI17/BU17 -> 0 | EK17: =CJ17/BU17 -> 1 | EL17: =CK17/BU17 -> 0 | EM17: =CL17/BU17 -> 0 | EN17: =CM17/BU17 -> 0 | EO17: =CN17/BU17 -> 0 | EP17: =CO17/BV17 -> 1 | EQ17: =CP17/BV17 -> 0 | ER17: =CQ17/BV17 -> 0 | ES17: =CR17/BV17 -> 0 | ET17: =CS17/BV17 -> 0 | EU17: =CT17/BW17 -> 1 | EV17: =CU17/BW17 -> 0 | EW17: =CV17/BW17 -> 0 | EX17: =CW17/BW17 -> 0 | EY17: =CX17/BX17 -> 1 | EZ17: =CY17/BX17 -> 0 | FA17: =CZ17/BX17 -> 0 | FB17: =DA17/BX17 -> 0 | FC17: =DB17/BX17 -> 0 | FD17: =DC17/BY17 -> 1 | FE17: =DD17/BY17 -> 0 | FF17: =DE17/BY17 -> 0 | FG17: =DF17/BY17 -> 0 | FH17: =DG17/BZ17 -> 0.7765964 | FI17: =DH17/BZ17 -> 0.2234036 | FJ17: =DI17/BZ17 -> 0 | FK17: =DJ17/BZ17 -> 0 | FL17: =DK17/BZ17 -> 0 | FM17: =DL17/CA17 -> 1 | FN17: =DM17/CA17 -> 0 | FO17: =DN17/CA17 -> 0 | FP17: =DO17/CA17 -> 0 | FQ17: =DP17/CA17 -> 0 | FR17: =DQ17/CA17 -> 0 | FS17: 0 | FT17: 0 | FU17: 0 | FV17: 0 | FW17: 0 | FX17: 0 | FY17: 0 | FZ17: 0 | GA17: =DZ17/CC17 -> 0.73342639 | GB17: =EA17/CC17 -> 0.26657361 | GC17: =EB17/CC17 -> 0 | GD17: =EC17/CC17 -> 0 | GE17: =ED17/CC17 -> 0
